Workbook
Name TRANSFER: #REF!
Name TRANSFER: #REF!
Name ID: 'INVONTERY FEB'!$A$6:$A$131
Name MANAGER: #REF!
Name DEPARTMENT: #REF!
Name TOTAL_CHICKEN_AMOUNT: #REF!
Name TRANSFER: #REF!
Name TRANSFER: #REF!
Name DEPARTMENT: #REF!
Name DEPARTMENT: #REF!
Name MANAGER: #REF!
Name SUPPLIERS: 'AMOUNT UPDATE'!$B$4:$B$19
Name MANAGER: #REF!

Sheet P&L WITH EXP.
A1: TU
A2: 45839
A3: DETAILS | B3: Actual | C3: %
A4: Product Sales | B4: ='DAILY UPDATE'!BR36 -> 2800162 | C4: 1
A5: FOOD | B5: ='INVONTERY FEB'!P108 -> 1379224.3 | C5: =B5/B$4 -> 0.4925516
A6: PAPER ITEMS | B6: ='INVONTERY FEB'!P131 -> 56947 | C6: =B6/B$4 -> 0.020337038
A7: DISTRIBUTION COST | B7: =SUMIF(EXPENSES!$B:$B,'P&L WITH EXP.'!A7,EXPENSES!$F:$F) -> 20500 | C7: =B7/B$4 -> 0.007321005
A8: CLEANING | B8: ='INVONTERY FEB'!P147 -> 1849 | C8: =B8/B$4 -> 0.00066031894
A9: PAYROLL | B9: =SUMIF(EXPENSES!$B:$B,'P&L WITH EXP.'!A9,EXPENSES!$F:$F) -> 390667 | C9: =B9/B$4 -> 0.13951586
A10: EMPLOYEE MEAL | B10: =SUMIF(EXPENSES!$B:$B,'P&L WITH EXP.'!A10,EXPENSES!$F:$F) -> 45000 | C10: =B10/B$4 -> 0.016070499
A11: APARTMENT | B11: =SUMIF(EXPENSES!$B:$B,'P&L WITH EXP.'!A11,EXPENSES!$F:$F) -> 0 | C11: =B11/B$4 -> 0
A12: M&R | B12: =SUMIF(EXPENSES!$B:$B,'P&L WITH EXP.'!A12,EXPENSES!$F:$F) -> 0 | C12: =B12/B$4 -> 0
A13: UNIFORM | B13: =SUMIF(EXPENSES!$B:$B,'P&L WITH EXP.'!A13,EXPENSES!$F:$F) -> 0 | C13: =B13/B$4 -> 0
A14: UTILITIES | B14: =SUMIF(EXPENSES!$B:$B,'P&L WITH EXP.'!A14,EXPENSES!$F:$F) -> 283634 | C14: =B14/B$4 -> 0.101292
A15: CROCKERY | B15: =SUMIF(EXPENSES!$B:$B,'P&L WITH EXP.'!A15,EXPENSES!$F:$F) -> 0 | C15: =B15/B$4 -> 0
A17: Total Con. Exp | B17: =SUM(B5:B16) -> 2177821.3 | C17: =B17/B$4 -> 0.77774832
A19: PAC | B19: =B4-B17 -> 622340.72 | C19: =B19/B$4 -> 0.22225168
A21: DIRECTOR | B21: =SUMIF(EXPENSES!$B:$B,'P&L WITH EXP.'!A21,EXPENSES!$F:$F) -> 620000 | C21: =B21/B$4 -> 0.22141576
A23: REMAINING CASH | B23: =B19-B21 -> 2340.7175 | C23: =B23/B$4 -> 0.00083592218
A24: TOTAL EXP AMOUNT | B24: =+B21+B17 -> 2797821.3
A26: CASH DETAIL
A27: OP. CASH | B27: ='DAILY UPDATE'!BQ5 -> 420
A28: SALE | B28: =B4 -> 2800162
A29: EXP | B29: =EXPENSES!F1 -> 2796174
A30: BAL | B30: =B27+B29-B29 -> 420
A31: DIFF | B31: =+B30-B27 -> 0
A32: DIFF FROM PNL CASH | B32: =+B23-B31 -> 2340.7175
A33: INVENTORY | B33: CURRENT MONTH | C33: LAST MONTH | D33: DIFF
A34: ='INVONTERY FEB'!C326 -> PHYSICAL INVENTORY | B34: ='INVONTERY FEB'!L326 -> 2010397.1 | C34: ='INVONTERY FEB'!F326 -> 2019838 | D34: =+B34-C34 -> -9440.906
A35: ='INVONTERY FEB'!C327 -> CREDIT AMOUNT | B35: ='INVONTERY FEB'!L327 -> -0.37652036 | C35: ='INVONTERY FEB'!F327 -> 0 | D35: =+B35-C35 -> -0.37652036
A36: ='INVONTERY FEB'!C328 -> STOCK IN HAND | B36: ='INVONTERY FEB'!L328 -> 2010396.8 | C36: ='INVONTERY FEB'!F328 -> 2019838 | D36: =+B36-C36 -> -9441.2825
A38: CASH HANDOVER | B38: =+B21 -> 620000
A39: CASH DIFF | B39: =+B31 -> 0
A40: STOCK DIFF | B40: =+D36 -> -9441.2825
A41: ACTUAL PROFIT & LOSS | B41: =+B40+B39+B38 -> 610558.72

Sheet PURCHASE
A1: (PURCHASE / STOCK IN/ RECEIVE) PRODUCTS FROM VENDOR
A2: INV # | B2: DATE | C2: SUPPLIER NAME | D2: ID | E2: PRODUCT DETAIL | F2: UNIT | G2: RATE | H2: QTY | I2: CREDIT AMOUNT | J2: DEBIT AMOUNT | K2: COMMENTS
B3: 46055 | C3: ELAHE EGGS TRADER | D3: 7 | E3: =IFERROR(VLOOKUP(D3,'INVONTERY FEB'!$A$6:$B$432,2,FALSE),"") -> EGGS | F3: =IFERROR(VLOOKUP(E3,'INVONTERY FEB'!$B$6:$C$432,2,FALSE),"") -> PCS | G3: =20600/720 -> 28.611111 | H3: 720 | I3: =IFERROR((H3*G3),"") -> 20600
B4: 46056 | C4: MIAN SHOUKAT TRADERS | D4: 42 | E4: =IFERROR(VLOOKUP(D4,'INVONTERY FEB'!$A$6:$B$432,2,FALSE),"") -> PISTACHIO SAPREAD | F4: =IFERROR(VLOOKUP(E4,'INVONTERY FEB'!$B$6:$C$432,2,FALSE),"") -> KG | G4: =IFERROR(VLOOKUP(E4,'INVONTERY FEB'!$B$6:$D$131,3,FALSE),"") -> 5200 | H4: 9 | I4: =IFERROR((H4*G4),"") -> 46800
B5: 46057 | C5: ELAHE EGGS TRADER | D5: 7 | E5: =IFERROR(VLOOKUP(D5,'INVONTERY FEB'!$A$6:$B$432,2,FALSE),"") -> EGGS | F5: =IFERROR(VLOOKUP(E5,'INVONTERY FEB'!$B$6:$C$432,2,FALSE),"") -> PCS | G5: =9500/360 -> 26.388889 | H5: 360 | I5: =IFERROR((H5*G5),"") -> 9500
B6: 46057 | C6: HAFFIZ MAHMOOD | D6: 56 | E6: =IFERROR(VLOOKUP(D6,'INVONTERY FEB'!$A$6:$B$432,2,FALSE),"") -> FERRY ROSE | F6: =IFERROR(VLOOKUP(E6,'INVONTERY FEB'!$B$6:$C$432,2,FALSE),"") -> BOX | G6: =IFERROR(VLOOKUP(E6,'INVONTERY FEB'!$B$6:$D$131,3,FALSE),"") -> 1000 | H6: 10 | I6: =IFERROR((H6*G6),"") -> 10000
B7: 46057 | C7: HAFFIZ MAHMOOD | D7: 37 | E7: =IFERROR(VLOOKUP(D7,'INVONTERY FEB'!$A$6:$B$432,2,FALSE),"") -> HISS CHOCLATE 2 RINGS | F7: =IFERROR(VLOOKUP(E7,'INVONTERY FEB'!$B$6:$C$432,2,FALSE),"") -> BOX | G7: =16000/18 -> 888.88889 | H7: 18 | I7: =IFERROR((H7*G7),"") -> 16000
B8: 46057 | C8: HAFFIZ MAHMOOD | D8: 38 | E8: =IFERROR(VLOOKUP(D8,'INVONTERY FEB'!$A$6:$B$432,2,FALSE),"") -> DAIRY MILK | F8: =IFERROR(VLOOKUP(E8,'INVONTERY FEB'!$B$6:$C$432,2,FALSE),"") -> BOX | G8: =10500/24 -> 437.5 | H8: 24 | I8: =IFERROR((H8*G8),"") -> 10500
B9: 46057 | C9: HAFFIZ MAHMOOD | D9: 50 | E9: =IFERROR(VLOOKUP(D9,'INVONTERY FEB'!$A$6:$B$432,2,FALSE),"") -> ALMONDS | F9: =IFERROR(VLOOKUP(E9,'INVONTERY FEB'!$B$6:$C$432,2,FALSE),"") -> KG | G9: =13250/5 -> 2650 | H9: 5 | I9: =IFERROR((H9*G9),"") -> 13250
B10: 46057 | C10: HAFFIZ MAHMOOD | D10: 52 | E10: =IFERROR(VLOOKUP(D10,'INVONTERY FEB'!$A$6:$B$432,2,FALSE),"") -> PISTACHIO | F10: =IFERROR(VLOOKUP(E10,'INVONTERY FEB'!$B$6:$C$432,2,FALSE),"") -> KG | G10: =18600/3 -> 6200 | H10: 3 | I10: =IFERROR((H10*G10),"") -> 18600
B11: 46057 | C11: HAFFIZ MAHMOOD | D11: 83 | E11: =IFERROR(VLOOKUP(D11,'INVONTERY FEB'!$A$6:$B$432,2,FALSE),"") -> RED SPONCH FOOD COLOUR 400GMS | F11: =IFERROR(VLOOKUP(E11,'INVONTERY FEB'!$B$6:$C$432,2,FALSE),"") -> BOTT | G11: =IFERROR(VLOOKUP(E11,'INVONTERY FEB'!$B$6:$D$131,3,FALSE),"") -> 650 | H11: 2 | I11: =IFERROR((H11*G11),"") -> 1300
B12: 46057 | C12: HAFFIZ MAHMOOD | D12: 13 | E12: =IFERROR(VLOOKUP(D12,'INVONTERY FEB'!$A$6:$B$432,2,FALSE),"") -> BAKING POWDER HOLIDAY | F12: =IFERROR(VLOOKUP(E12,'INVONTERY FEB'!$B$6:$C$432,2,FALSE),"") -> KG | G12: =IFERROR(VLOOKUP(E12,'INVONTERY FEB'!$B$6:$D$131,3,FALSE),"") -> 2000 | H12: 5 | I12: =IFERROR((H12*G12),"") -> 10000
B13: 46057 | C13: LOCAL MARKET | D13: 56 | E13: =IFERROR(VLOOKUP(D13,'INVONTERY FEB'!$A$6:$B$432,2,FALSE),"") -> FERRY ROSE | F13: =IFERROR(VLOOKUP(E13,'INVONTERY FEB'!$B$6:$C$432,2,FALSE),"") -> BOX | G13: =IFERROR(VLOOKUP(E13,'INVONTERY FEB'!$B$6:$D$131,3,FALSE),"") -> 1000 | H13: 1 | I13: =IFERROR((H13*G13),"") -> 1000
B14: 46057 | C14: LOCAL MARKET | D14: 122 | E14: =IFERROR(VLOOKUP(D14,'INVONTERY FEB'!$A$6:$B$432,2,FALSE),"") -> DISSPOSSABLE PACKING | F14: =IFERROR(VLOOKUP(E14,'INVONTERY FEB'!$B$6:$C$432,2,FALSE),"") -> PCS | G14: =4200/600 -> 7 | H14: 600 | I14: =IFERROR((H14*G14),"") -> 4200
B15: 46058 | C15: ELAHE EGGS TRADER | D15: 7 | E15: =IFERROR(VLOOKUP(D15,'INVONTERY FEB'!$A$6:$B$432,2,FALSE),"") -> EGGS | F15: =IFERROR(VLOOKUP(E15,'INVONTERY FEB'!$B$6:$C$432,2,FALSE),"") -> PCS | G15: =9000/360 -> 25 | H15: 360 | I15: =IFERROR((H15*G15),"") -> 9000
B16: 46061 | C16: ELAHE EGGS TRADER | D16: 7 | E16: =IFERROR(VLOOKUP(D16,'INVONTERY FEB'!$A$6:$B$432,2,FALSE),"") -> EGGS | F16: =IFERROR(VLOOKUP(E16,'INVONTERY FEB'!$B$6:$C$432,2,FALSE),"") -> PCS | G16: =9000/360 -> 25 | H16: 360 | I16: =IFERROR((H16*G16),"") -> 9000
B17: 46062 | C17: ELAHE EGGS TRADER | D17: 7 | E17: =IFERROR(VLOOKUP(D17,'INVONTERY FEB'!$A$6:$B$432,2,FALSE),"") -> EGGS | F17: =IFERROR(VLOOKUP(E17,'INVONTERY FEB'!$B$6:$C$432,2,FALSE),"") -> PCS | G17: =8500/360 -> 23.611111 | H17: 360 | I17: =IFERROR((H17*G17),"") -> 8500
B18: 46062 | C18: S.N TRADERS | D18: 43 | E18: =IFERROR(VLOOKUP(D18,'INVONTERY FEB'!$A$6:$B$432,2,FALSE),"") -> OLPERS CREAM 200 ML | F18: =IFERROR(VLOOKUP(E18,'INVONTERY FEB'!$B$6:$C$432,2,FALSE),"") -> PCS | G18: =IFERROR(VLOOKUP(E18,'INVONTERY FEB'!$B$6:$D$131,3,FALSE),"") -> 207.28197 | H18: 240 | I18: =IFERROR((H18*G18),"") -> 49747.672
B19: 46062 | C19: LOCAL MARKET | D19: 31 | E19: =IFERROR(VLOOKUP(D19,'INVONTERY FEB'!$A$6:$B$432,2,FALSE),"") -> NURPUR BUTTER | F19: =IFERROR(VLOOKUP(E19,'INVONTERY FEB'!$B$6:$C$432,2,FALSE),"") -> KG | G19: =19500/10 -> 1950 | H19: 10 | I19: =IFERROR((H19*G19),"") -> 19500
B20: 46062 | C20: MIAN SHOUKAT TRADERS | D20: 61 | E20: =IFERROR(VLOOKUP(D20,'INVONTERY FEB'!$A$6:$B$432,2,FALSE),"") -> LOTO SPREAD 400G | F20: =IFERROR(VLOOKUP(E20,'INVONTERY FEB'!$B$6:$C$432,2,FALSE),"") -> PCS | G20: =IFERROR(VLOOKUP(E20,'INVONTERY FEB'!$B$6:$D$131,3,FALSE),"") -> 1750 | H20: =12*12 -> 144 | I20: =IFERROR((H20*G20),"") -> 252000
B21: 46063 | C21: MIAN SHOUKAT TRADERS | D21: 47 | E21: =IFERROR(VLOOKUP(D21,'INVONTERY FEB'!$A$6:$B$432,2,FALSE),"") -> LOTUS BISCOFF | F21: =IFERROR(VLOOKUP(E21,'INVONTERY FEB'!$B$6:$C$432,2,FALSE),"") -> PKT | G21: =IFERROR(VLOOKUP(E21,'INVONTERY FEB'!$B$6:$D$131,3,FALSE),"") -> 1100 | H21: 50 | I21: =IFERROR((H21*G21),"") -> 55000
B22: 46064 | C22: MIAN SHOUKAT TRADERS | D22: 29 | E22: =IFERROR(VLOOKUP(D22,'INVONTERY FEB'!$A$6:$B$432,2,FALSE),"") -> WHIPPING CREAM | F22: =IFERROR(VLOOKUP(E22,'INVONTERY FEB'!$B$6:$C$432,2,FALSE),"") -> PCS | G22: =IFERROR(VLOOKUP(E22,'INVONTERY FEB'!$B$6:$D$131,3,FALSE),"") -> 700 | H22: 216 | I22: =IFERROR((H22*G22),"") -> 151200
B23: 46064 | C23: MIAN SHOUKAT TRADERS | D23: 10 | E23: =IFERROR(VLOOKUP(D23,'INVONTERY FEB'!$A$6:$B$432,2,FALSE),"") -> COCO POWDER MALASIAN | F23: =IFERROR(VLOOKUP(E23,'INVONTERY FEB'!$B$6:$C$432,2,FALSE),"") -> KG | G23: =195800/50 -> 3916 | H23: 50 | I23: =IFERROR((H23*G23),"") -> 195800
B24: 46064 | C24: BAKERZ SOLUTIONS | D24: 98 | E24: =IFERROR(VLOOKUP(D24,'INVONTERY FEB'!$A$6:$B$432,2,FALSE),"") -> VIBGOR FOOD COLOUR | F24: =IFERROR(VLOOKUP(E24,'INVONTERY FEB'!$B$6:$C$432,2,FALSE),"") -> BOTT | G24: =1875/3 -> 625 | H24: 3 | I24: =IFERROR((H24*G24),"") -> 1875
B25: 46064 | C25: ELAHE EGGS TRADER | D25: 7 | E25: =IFERROR(VLOOKUP(D25,'INVONTERY FEB'!$A$6:$B$432,2,FALSE),"") -> EGGS | F25: =IFERROR(VLOOKUP(E25,'INVONTERY FEB'!$B$6:$C$432,2,FALSE),"") -> PCS | G25: =8500/360 -> 23.611111 | H25: 360 | I25: =IFERROR((H25*G25),"") -> 8500
B26: 46064 | C26: HAFFIZ MAHMOOD | D26: 19 | E26: =IFERROR(VLOOKUP(D26,'INVONTERY FEB'!$A$6:$B$432,2,FALSE),"") -> GULCOSE LIQUID | F26: =IFERROR(VLOOKUP(E26,'INVONTERY FEB'!$B$6:$C$432,2,FALSE),"") -> BOTT | G26: =1750/1 -> 1750 | H26: 1 | I26: =IFERROR((H26*G26),"") -> 1750
B27: 46064 | C27: HAFFIZ MAHMOOD | D27: 8 | E27: =IFERROR(VLOOKUP(D27,'INVONTERY FEB'!$A$6:$B$432,2,FALSE),"") -> POLAC CONDENSED MILK 1-LTR | F27: =IFERROR(VLOOKUP(E27,'INVONTERY FEB'!$B$6:$C$432,2,FALSE),"") -> TIN | G27: =11900/17 -> 700 | H27: 17 | I27: =IFERROR((H27*G27),"") -> 11900
B28: 46065 | C28: ELAHE EGGS TRADER | D28: 7 | E28: =IFERROR(VLOOKUP(D28,'INVONTERY FEB'!$A$6:$B$432,2,FALSE),"") -> EGGS | F28: =IFERROR(VLOOKUP(E28,'INVONTERY FEB'!$B$6:$C$432,2,FALSE),"") -> PCS | G28: =8500/360 -> 23.611111 | H28: 360 | I28: =IFERROR((H28*G28),"") -> 8500
B29: 46066 | C29: NESTLE | D29: 28 | E29: =IFERROR(VLOOKUP(D29,'INVONTERY FEB'!$A$6:$B$432,2,FALSE),"") -> NESTLE BUTTER | F29: =IFERROR(VLOOKUP(E29,'INVONTERY FEB'!$B$6:$C$432,2,FALSE),"") -> KG | G29: =IFERROR(VLOOKUP(E29,'INVONTERY FEB'!$B$6:$D$131,3,FALSE),"") -> 1850 | H29: 20 | I29: =IFERROR((H29*G29),"") -> 37000
B30: 46066 | C30: ELAHE EGGS TRADER | D30: 7 | E30: =IFERROR(VLOOKUP(D30,'INVONTERY FEB'!$A$6:$B$432,2,FALSE),"") -> EGGS | F30: =IFERROR(VLOOKUP(E30,'INVONTERY FEB'!$B$6:$C$432,2,FALSE),"") -> PCS | G30: =8500/360 -> 23.611111 | H30: 360 | I30: =IFERROR((H30*G30),"") -> 8500
B31: 46066 | C31: LOCAL MARKET | D31: 138 | E31: =IFERROR(VLOOKUP(D31,'INVONTERY FEB'!$A$6:$B$432,2,FALSE),"") -> DUSTER | F31: =IFERROR(VLOOKUP(E31,'INVONTERY FEB'!$B$6:$C$432,2,FALSE),"") -> KG | G31: =25069/58.3 -> 430 | H31: 58.3 | I31: =IFERROR((H31*G31),"") -> 25069
B32: 46067 | C32: ELAHE EGGS TRADER | D32: 7 | E32: =IFERROR(VLOOKUP(D32,'INVONTERY FEB'!$A$6:$B$432,2,FALSE),"") -> EGGS | F32: =IFERROR(VLOOKUP(E32,'INVONTERY FEB'!$B$6:$C$432,2,FALSE),"") -> PCS | G32: =8000/360 -> 22.222222 | H32: 360 | I32: =IFERROR((H32*G32),"") -> 8000
B33: 46067 | C33: BAKERZ SOLUTIONS | D33: 85 | E33: =IFERROR(VLOOKUP(D33,'INVONTERY FEB'!$A$6:$B$432,2,FALSE),"") -> VIBGYOR BASE FOUNDANT COLOURE | F33: =IFERROR(VLOOKUP(E33,'INVONTERY FEB'!$B$6:$C$432,2,FALSE),"") -> BOTT | G33: =11130/9 -> 1236.6667 | H33: 9 | I33: =IFERROR((H33*G33),"") -> 11130
B34: 46067 | C34: BAKERZ SOLUTIONS | D34: 96 | E34: =IFERROR(VLOOKUP(D34,'INVONTERY FEB'!$A$6:$B$432,2,FALSE),"") -> SILVER EATABLE COLOURE | F34: =IFERROR(VLOOKUP(E34,'INVONTERY FEB'!$B$6:$C$432,2,FALSE),"") -> BOTT | G34: =1000/1 -> 1000 | H34: 1 | I34: =IFERROR((H34*G34),"") -> 1000
B35: 46067 | C35: S.N TRADERS | D35: 9 | E35: =IFERROR(VLOOKUP(D35,'INVONTERY FEB'!$A$6:$B$432,2,FALSE),"") -> OLPERS MILK 1.5 LTR | F35: =IFERROR(VLOOKUP(E35,'INVONTERY FEB'!$B$6:$C$432,2,FALSE),"") -> PCS | G35: =39195/80 -> 489.9375 | H35: 80 | I35: =IFERROR((H35*G35),"") -> 39195
B36: 46068 | C36: ELAHE EGGS TRADER | D36: 7 | E36: =IFERROR(VLOOKUP(D36,'INVONTERY FEB'!$A$6:$B$432,2,FALSE),"") -> EGGS | F36: =IFERROR(VLOOKUP(E36,'INVONTERY FEB'!$B$6:$C$432,2,FALSE),"") -> PCS | G36: =7500/360 -> 20.833333 | H36: 360 | I36: =IFERROR((H36*G36),"") -> 7500
B37: 46068 | C37: LOCAL MARKET | D37: 108 | E37: =IFERROR(VLOOKUP(D37,'INVONTERY FEB'!$A$6:$B$432,2,FALSE),"") -> PAPER TRAY 5 POUND | F37: =IFERROR(VLOOKUP(E37,'INVONTERY FEB'!$B$6:$C$432,2,FALSE),"") -> PCS | G37: =IFERROR(VLOOKUP(E37,'INVONTERY FEB'!$B$6:$D$131,3,FALSE),"") -> 40 | H37: 20 | I37: =IFERROR((H37*G37),"") -> 800
B38: 46068 | C38: LOCAL MARKET | D38: 110 | E38: =IFERROR(VLOOKUP(D38,'INVONTERY FEB'!$A$6:$B$432,2,FALSE),"") -> PAPER TRAY 7 POUND | F38: =IFERROR(VLOOKUP(E38,'INVONTERY FEB'!$B$6:$C$432,2,FALSE),"") -> PCS | G38: =1100/20 -> 55 | H38: 20 | I38: =IFERROR((H38*G38),"") -> 1100
B39: 46068 | C39: LOCAL MARKET | D39: 111 | E39: =IFERROR(VLOOKUP(D39,'INVONTERY FEB'!$A$6:$B$432,2,FALSE),"") -> PAPER TRAY 8 POUND | F39: =IFERROR(VLOOKUP(E39,'INVONTERY FEB'!$B$6:$C$432,2,FALSE),"") -> PCS | G39: =1300/20 -> 65 | H39: 20 | I39: =IFERROR((H39*G39),"") -> 1300
B40: 46068 | C40: LOCAL MARKET | D40: 107 | E40: =IFERROR(VLOOKUP(D40,'INVONTERY FEB'!$A$6:$B$432,2,FALSE),"") -> CAKE SHEET 4 POUND | F40: =IFERROR(VLOOKUP(E40,'INVONTERY FEB'!$B$6:$C$432,2,FALSE),"") -> PKT | G40: =700/20 -> 35 | H40: 20 | I40: =IFERROR((H40*G40),"") -> 700
...

Sheet EXPENSES
F1: =SUM(F3:F840) -> 2796174 | G1: =SUM(G3:G840) -> 2796174 | H1: =G1-'DAILY UPDATE'!#REF! -> #ERROR! | K1: =G1-F1 -> 0
A2: DATE | B2: HEAD | C2: ID | D2: SUB HEAD | E2: DETAIL | F2: AMOUNT | G2: TOTAL | H2: UNIT | I2: QTY | J2: RATE | K2: VENDOR
A3: 46057 | B3: EMPLOYEE MEAL | D3: MEAL | E3: BAKERY TEAM MEAL MA/O FEB | F3: 40475
A4: 46057 | B4: FOOD | D4: SPONGEE | E4: EGGS | F4: 30100 | K4: ELAHE EGGS TRADER
A5: 46057 | B5: FOOD | D5: CAKE TOPPING | E5: FERRARO CHOCLATE | F5: 1000 | K5: LOCAL MARKET
A6: 46057 | B6: PAPER ITEM | D6: PAPER ITEM | E6: DISSPOSSABLE PACKING | F6: 4200 | H6: PCS | I6: 600 | J6: =4200/600 -> 7 | K6: LOCAL MARKET
A7: 46057 | B7: FOUNDANT | D7: ORDER CAKE | E7: ORDER CAKE PICS AND FLOWER | F7: 2010
A8: 46057 | B8: DISTRIBUTION COST | D8: EVAN FUEL | E8: EVAN FUEL | F8: 3000
A9: 46057 | B9: DISTRIBUTION COST | D9: AUTO RENT | E9: AUTO RENT | F9: 300
A10: 46057 | B10: UTILITIES | D10: PTCL | E10: PTCL BILL PAID M/O FEB | F10: 5310
A11: 46057 | B11: UTILITIES | D11: FUMIGATION | E11: FUMIGATION | F11: 8000
A12: 46057 | B12: MISC | D12: MISC | E12: BAKERY WASHROOM MIROR AND CEMRA WIRE COVERD | F12: 2480 | G12: =SUM(F3:F12) -> 96875
A13: 46061 | B13: EMPLOYEE MEAL | D13: MEAL | E13: BAKERY TEAM MEAL MA/O FEB | F13: 3525
A14: 46061 | B14: FOOD | D14: SPONGEE | E14: EGGS | F14: 26500 | K14: ELAHE EGGS TRADER
A15: 46061 | B15: FOOD | D15: CAKE CREAM | E15: BUTTER | F15: 19500 | K15: LOCAL MARKET
A16: 46061 | B16: PAYROLL | D16: SALARY | E16: BAKERY TEAM SALARY M/O JAN | F16: 286167
A17: 46061 | B17: FOUNDANT | D17: ORDER CAKE | E17: ORDER CAKE FLOWERS AND TOOTH PICK STICKS | F17: 1990
A18: 46061 | B18: FOUNDANT | D18: ORDER CAKE | E18: ORDER CAKE PIC | F18: 150
A19: 46061 | B19: DISTRIBUTION COST | D19: EVAN FUEL | E19: EVAN FUEL | F19: 6000
A20: 46061 | B20: UTILITIES | D20: FESCO | E20: BAKERY DEPARTMENT FESCO BILL PAID M/O FEB | F20: 136234
A21: 46061 | B21: UTILITIES | D21: RENT | E21: BAKERY TEAM HOME RENT M/O JAN | F21: 28480
A22: 46061 | B22: MISC | D22: M&R | E22: BAKERY DISHWASHING SPINDEL CHANGE | F22: 600 | G22: =SUM(F13:F22) -> 509146
A23: 46063 | B23: FOOD | D23: CAKE CREAM | E23: PISTA SAPREAD | F23: 46800 | K23: MIAN SHOUKAT TRADERS
A24: 46063 | B24: UTILITIES | D24: RENT | E24: IKRAM HOME RENT M/O JAN | F24: 8000
A25: 46063 | B25: FOUNDANT | D25: ORDER CAKE | E25: ORDER CAKE PICS AND FLOWERS | F25: 1830 | G25: =SUM(F23:F25) -> 56630
A26: 46064 | B26: DIRECTOR | D26: YASIR SB | E26: CASH HAND OVER TO YASIR SB | F26: 350000
A27: 46064 | B27: FOOD | D27: SPONGEE | E27: EGGS | F27: 17000 | K27: ELAHE EGGS TRADER
A28: 46064 | B28: FOOD | D28: CAKE TOPPING | E28: FOOD COLOURE | F28: 1875 | K28: BAKERZ SOLUTIONS
A29: 46066 | B29: PAYROLL | D29: SAJID | E29: SAJID BAKERY CASH CHARGE TO SALARY | F29: 15000 | G29: =SUM(F26:F29) -> 383875
A30: 46066 | B30: FOOD | D30: SPONGEE | E30: EGGS | F30: 16500 | K30: ELAHE EGGS TRADER
A31: 46066 | B31: FOOD | D31: ORDER CAKE | E31: FOUNDANT | F31: 11130 | K31: BAKERZ SOLUTIONS
A32: 46066 | B32: FOOD | D32: ORDER CAKE | E32: FOOD COLOURE | F32: 1000 | K32: BAKERZ SOLUTIONS
A33: 46066 | B33: CLEANING | D33: CLEANING | E33: DUSTER | F33: 25069 | K33: LOCAL MARKET
A34: 46066 | B34: FOUNDANT | D34: ORDER CAKE | E34: ORDER CAKE BOWL | F34: 350
A35: 46066 | B35: FOUNDANT | D35: ORDER CAKE | E35: ORDER CAKE PIPE | F35: 500
A36: 46066 | B36: FOUNDANT | D36: ORDER CAKE | E36: ORDER CAKE PIC | F36: 450
A37: 46066 | B37: FOUNDANT | D37: ORDER CAKE | E37: ORDER CAKE SHEET | F37: 400 | G37: =SUM(F30:F37) -> 55399
A38: 46068 | B38: FOOD | D38: CAKE TOPPING | E38: HAFIZ MEHMOOD PAYMENT | F38: 93300 | K38: HAFFIZ MAHMOOD
A39: 46068 | B39: FOOD | D39: SPONGEE | E39: EGGS | F39: 7500 | K39: ELAHE EGGS TRADER
A40: 46068 | B40: FOOD | D40: CAKE CREAM | E40: SHUKAT TRADERS PAYMENT | F40: 307000 | K40: MIAN SHOUKAT TRADERS
...

Sheet INVONTERY FEB
A2: INVENTORY REPORT
A3: ID | B3: PRODUCT DETAIL | C3: UNIT | D3: RATE | E3: OPENING INV | F3: OPENING AMOUNT | G3: PURCHASE | I3: ISSUE | J3: DAILY USAGE AVERAGE | K3: CLOSING INV | L3: CLOSING AMOUNT | M3: NEW RATE | N3: PRICE COMP. | O3: COST INCREASE | P3: COST | Q3: COMPANY NAME
G4: QTY | H4: AMOUNT
A5: 1.1 | B5: SPONAGE | S5: EOD | T5: OUT | U5: OUT | V5: OPENING
A6: 1 | B6: RED VELVET CONCENTRATE 10 KG | C6: KG | F6: =E6*D6 -> 0 | G6: =SUMIF(PURCHASE!$E$3:$E$506,'INVONTERY FEB'!B6:B326,PURCHASE!$H$3:$H$506) -> 0 | H6: =SUMIF(PURCHASE!$E$3:$E$506,'INVONTERY FEB'!B6:B326,PURCHASE!$I$3:$I$506) -> 0 | I6: =ISSU!AL6 -> 0 | J6: =I6/9 -> 0 | K6: =E6+G6-I6 -> 0 | L6: =K6*M6 -> 0 | N6: =M6-D6 -> 0 | O6: =N6*I6 -> 0 | P6: =F6+H6-L6 -> 0 | Q6: VENUS | S6: 0 | V6: =+S6+T6+U6 -> 0
A7: 2 | B7: LA OLA CONCENTRATE | C7: KG | F7: =E7*D7 -> 0 | G7: =SUMIF(PURCHASE!$E$3:$E$506,'INVONTERY FEB'!B7:B327,PURCHASE!$H$3:$H$506) -> 0 | H7: =SUMIF(PURCHASE!$E$3:$E$506,'INVONTERY FEB'!B7:B327,PURCHASE!$I$3:$I$506) -> 0 | I7: =ISSU!AL7 -> 0 | J7: =I7/9 -> 0 | K7: =E7+G7-I7 -> 0 | L7: =K7*M7 -> 0 | N7: =M7-D7 -> 0 | O7: =N7*I7 -> 0 | P7: =F7+H7-L7 -> 0 | Q7: LOCAL | S7: 0 | V7: =+S7+T7+U7 -> 0
A8: 3 | B8: AUSTRIA SPONGE MIX CONCENTRATE (269) | C8: KG | F8: =E8*D8 -> 0 | G8: =SUMIF(PURCHASE!$E$3:$E$506,'INVONTERY FEB'!B8:B328,PURCHASE!$H$3:$H$506) -> 0 | H8: =SUMIF(PURCHASE!$E$3:$E$506,'INVONTERY FEB'!B8:B328,PURCHASE!$I$3:$I$506) -> 0 | I8: =ISSU!AL8 -> 0 | J8: =I8/29 -> 0 | K8: =E8+G8-I8 -> 0 | L8: =K8*M8 -> 0 | N8: =M8-D8 -> 0 | O8: =N8*I8 -> 0 | P8: =F8+H8-L8 -> 0 | Q8: VENUS | S8: 0 | V8: =+S8+T8+U8 -> 0
A9: 4 | B9: KISAN CANOLA OIL 5 LTR | C9: BOX | D9: 560 | E9: 290 | F9: =E9*D9 -> 162400 | G9: =SUMIF(PURCHASE!$E$3:$E$506,'INVONTERY FEB'!B9:B328,PURCHASE!$H$3:$H$506) -> 0 | H9: =SUMIF(PURCHASE!$E$3:$E$506,'INVONTERY FEB'!B9:B328,PURCHASE!$I$3:$I$506) -> 0 | I9: =ISSU!AL9 -> 170 | J9: =I9/28 -> 6.0714286 | K9: =E9+G9-I9 -> 120 | L9: =K9*M9 -> 67200 | M9: =D9 -> 560 | N9: =M9-D9 -> 0 | O9: =N9*I9 -> 0 | P9: =F9+H9-L9 -> 95200 | Q9: VENUS | S9: 0 | V9: =+S9+T9+U9 -> 0
A10: 5 | B10: FLOUR | C10: BAG | D10: 134 | E10: 300 | F10: =E10*D10 -> 40200 | G10: =SUMIF(PURCHASE!$E$3:$E$506,'INVONTERY FEB'!B10:B328,PURCHASE!$H$3:$H$506) -> 0 | H10: =SUMIF(PURCHASE!$E$3:$E$506,'INVONTERY FEB'!B10:B328,PURCHASE!$I$3:$I$506) -> 0 | I10: =ISSU!AL10 -> 250 | J10: =I10/28 -> 8.9285714 | K10: =E10+G10-I10 -> 50 | L10: =K10*M10 -> 6700 | M10: =D10 -> 134 | N10: =M10-D10 -> 0 | O10: =N10*I10 -> 0 | P10: =F10+H10-L10 -> 33500 | Q10: LOCAL | U10: 1 | V10: =+S10+T10+U10 -> 1
A11: 6 | B11: LOSSE SUGAR 50KG | C11: KG | D11: 184 | E11: 300 | F11: =E11*D11 -> 55200 | G11: =SUMIF(PURCHASE!$E$3:$E$506,'INVONTERY FEB'!B11:B329,PURCHASE!$H$3:$H$506) -> 100 | H11: =SUMIF(PURCHASE!$E$3:$E$506,'INVONTERY FEB'!B11:B329,PURCHASE!$I$3:$I$506) -> 18400 | I11: =ISSU!AL11 -> 300 | J11: =I11/28 -> 10.714286 | K11: =E11+G11-I11 -> 100 | L11: =K11*M11 -> 18400 | M11: =D11 -> 184 | N11: =M11-D11 -> 0 | O11: =N11*I11 -> 0 | P11: =F11+H11-L11 -> 55200 | Q11: LOCAL | S11: =50*2 -> 100 | V11: =+S11+T11+U11 -> 100
A12: 7 | B12: EGGS | C12: PCS | D12: =5067/160 -> 31.66875 | E12: 380 | F12: =E12*D12 -> 12034.125 | G12: =SUMIF(PURCHASE!$E$3:$E$506,'INVONTERY FEB'!B12:B483,PURCHASE!$H$3:$H$506) -> 5040 | H12: =SUMIF(PURCHASE!$E$3:$E$506,'INVONTERY FEB'!B12:B433,PURCHASE!$I$3:$I$506) -> 120100 | I12: =ISSU!AL12 -> 5170 | J12: =I12/28 -> 184.64286 | K12: =E12+G12-I12 -> 250 | L12: =K12*M12 -> 7917.1875 | M12: =D12 -> 31.66875 | N12: =M12-D12 -> 0 | O12: =N12*I12 -> 0 | P12: =F12+H12-L12 -> 124216.94 | S12: 0 | V12: =+S12+T12+U12 -> 0
A13: 8 | B13: POLAC CONDENSED MILK 1-LTR | C13: TIN | D13: 625 | E13: 30 | F13: =E13*D13 -> 18750 | G13: =SUMIF(PURCHASE!$E$3:$E$506,'INVONTERY FEB'!B13:B501,PURCHASE!$H$3:$H$506) -> 89 | H13: =SUMIF(PURCHASE!$E$3:$E$506,'INVONTERY FEB'!B13:B451,PURCHASE!$I$3:$I$506) -> 56900 | I13: =ISSU!AL13 -> 54 | J13: =I13/28 -> 1.9285714 | K13: =E13+G13-I13 -> 65 | L13: =K13*M13 -> 40625 | M13: =D13 -> 625 | N13: =M13-D13 -> 0 | O13: =N13*I13 -> 0 | P13: =F13+H13-L13 -> 35025 | S13: 22 | T13: 2 | U13: 2 | V13: =+S13+T13+U13 -> 26
A14: 9 | B14: OLPERS MILK 1.5 LTR | C14: PCS | D14: =30263/62 -> 488.1129 | E14: 126 | F14: =E14*D14 -> 61502.226 | G14: =SUMIF(PURCHASE!$E$3:$E$506,'INVONTERY FEB'!B14:B490,PURCHASE!$H$3:$H$506) -> 160 | H14: =SUMIF(PURCHASE!$E$3:$E$506,'INVONTERY FEB'!B14:B440,PURCHASE!$I$3:$I$506) -> 78244.032 | I14: =ISSU!AL14 -> 190 | J14: =I14/28 -> 6.7857143 | K14: =E14+G14-I14 -> 96 | L14: =K14*M14 -> 46858.839 | M14: =D14 -> 488.1129 | N14: =M14-D14 -> 0 | O14: =N14*I14 -> 0 | P14: =F14+H14-L14 -> 92887.419 | Q14: LOCAL | S14: 8 | T14: 8 | V14: =+S14+T14+U14 -> 16
A15: 10 | B15: COCO POWDER MALASIAN | C15: KG | D15: =137098/35 -> 3917.0857 | E15: 57 | F15: =E15*D15 -> 223273.89 | G15: =SUMIF(PURCHASE!$E$3:$E$506,'INVONTERY FEB'!B15:B328,PURCHASE!$H$3:$H$506) -> 50 | H15: =SUMIF(PURCHASE!$E$3:$E$506,'INVONTERY FEB'!B15:B328,PURCHASE!$I$3:$I$506) -> 195800 | I15: =ISSU!AL15 -> 37 | J15: =I15/28 -> 1.3214286 | K15: =E15+G15-I15 -> 70 | L15: =K15*M15 -> 274196 | M15: =D15 -> 3917.0857 | N15: =M15-D15 -> 0 | O15: =N15*I15 -> 0 | P15: =F15+H15-L15 -> 144877.89 | Q15: LOCAL | S15: 0 | V15: =+S15+T15+U15 -> 0
A16: 11 | B16: VANILLA ESSENCE 500 GM | C16: BOTT | D16: 1150 | E16: 2 | F16: =E16*D16 -> 2300 | G16: =SUMIF(PURCHASE!$E$3:$E$506,'INVONTERY FEB'!B16:B341,PURCHASE!$H$3:$H$506) -> 12 | H16: =SUMIF(PURCHASE!$E$3:$E$506,'INVONTERY FEB'!B16:B336,PURCHASE!$I$3:$I$506) -> 13200 | I16: =ISSU!AL16 -> 5 | J16: =I16/28 -> 0.17857143 | K16: =E16+G16-I16 -> 9 | L16: =K16*M16 -> 10350 | M16: =D16 -> 1150 | N16: =M16-D16 -> 0 | O16: =N16*I16 -> 0 | P16: =F16+H16-L16 -> 5150 | Q16: K'E'H | S16: 0 | V16: =+S16+T16+U16 -> 0
A17: 12 | B17: SALT 800GM | C17: PKT | D17: 29 | E17: 0 | F17: =E17*D17 -> 0 | G17: =SUMIF(PURCHASE!$E$3:$E$506,'INVONTERY FEB'!B17:B344,PURCHASE!$H$3:$H$506) -> 0 | H17: =SUMIF(PURCHASE!$E$3:$E$506,'INVONTERY FEB'!B17:B339,PURCHASE!$I$3:$I$506) -> 0 | I17: =ISSU!AL17 -> 0 | J17: =I17/28 -> 0 | K17: =E17+G17-I17 -> 0 | L17: =K17*M17 -> 0 | M17: =D17 -> 29 | N17: =M17-D17 -> 0 | O17: =N17*I17 -> 0 | P17: =F17+H17-L17 -> 0 | S17: 0 | V17: =+S17+T17+U17 -> 0
A18: 13 | B18: BAKING POWDER HOLIDAY | C18: KG | D18: 2000 | E18: 0 | F18: =E18*D18 -> 0 | G18: =SUMIF(PURCHASE!$E$3:$E$506,'INVONTERY FEB'!B18:B362,PURCHASE!$H$3:$H$506) -> 5 | H18: =SUMIF(PURCHASE!$E$3:$E$506,'INVONTERY FEB'!B18:B362,PURCHASE!$I$3:$I$506) -> 10000 | I18: =ISSU!AL19 -> 3 | J18: =I18/28 -> 0.10714286 | K18: =E18+G18-I18 -> 2 | L18: =K18*M18 -> 4000 | M18: =D18 -> 2000 | N18: =M18-D18 -> 0 | O18: =N18*I18 -> 0 | P18: =F18+H18-L18 -> 6000 | Q18: LOCAL | S18: 0 | V18: =+S18+T18+U18 -> 0
A19: 14 | B19: BAKING SODA 1- KG | C19: KG | D19: 160 | E19: 5 | F19: =E19*D19 -> 800 | G19: =SUMIF(PURCHASE!$E$3:$E$506,'INVONTERY FEB'!B19:B338,PURCHASE!$H$3:$H$506) -> 0 | H19: =SUMIF(PURCHASE!$E$3:$E$506,'INVONTERY FEB'!B19:B333,PURCHASE!$I$3:$I$506) -> 0 | I19: =ISSU!AL18 -> 0 | J19: =I19/28 -> 0 | K19: =E19+G19-I19 -> 5 | L19: =K19*M19 -> 800 | M19: =D19 -> 160 | N19: =M19-D19 -> 0 | O19: =N19*I19 -> 0 | P19: =F19+H19-L19 -> 0 | Q19: LOCAL | S19: 0 | V19: =+S19+T19+U19 -> 0
A20: 15 | B20: STARCH | C20: KG | D20: 200 | E20: 5 | F20: =E20*D20 -> 1000 | G20: =SUMIF(PURCHASE!$E$3:$E$506,'INVONTERY FEB'!B20:B351,PURCHASE!$H$3:$H$506) -> 0 | H20: =SUMIF(PURCHASE!$E$3:$E$506,'INVONTERY FEB'!B20:B346,PURCHASE!$I$3:$I$506) -> 0 | I20: =ISSU!AL20 -> 0 | J20: =I20/28 -> 0 | K20: =E20+G20-I20 -> 5 | L20: =K20*M20 -> 1000 | M20: =D20 -> 200 | N20: =M20-D20 -> 0 | O20: =N20*I20 -> 0 | P20: =F20+H20-L20 -> 0 | Q20: LOCAL | V20: =+S20+T20+U20 -> 0
A21: 16 | B21: KHOYA ESSANSE | C21: PCS | E21: 0 | F21: =E21*D21 -> 0 | G21: =SUMIF(PURCHASE!$E$3:$E$506,'INVONTERY FEB'!B21:B377,PURCHASE!$H$3:$H$506) -> 0 | H21: =SUMIF(PURCHASE!$E$3:$E$506,'INVONTERY FEB'!B21:B375,PURCHASE!$I$3:$I$506) -> 0 | I21: =ISSU!AL21 -> 0 | J21: =I21/28 -> 0 | K21: =E21+G21-I21 -> 0 | L21: =K21*M21 -> 0 | M21: =D21 | N21: =M21-D21 -> 0 | O21: =N21*I21 -> 0 | P21: =F21+H21-L21 -> 0 | Q21: NESTLE | S21: 0 | V21: =+S21+T21+U21 -> 0
A22: 17 | B22: HABIB OIL 4.5 L BOT | C22: BOTT | F22: =E22*D22 -> 0 | G22: =SUMIF(PURCHASE!$E$3:$E$506,'INVONTERY FEB'!B22:B339,PURCHASE!$H$3:$H$506) -> 0 | H22: =SUMIF(PURCHASE!$E$3:$E$506,'INVONTERY FEB'!B22:B334,PURCHASE!$I$3:$I$506) -> 0 | I22: =ISSU!AL22 -> 0 | J22: =I22/30 -> 0 | K22: =E22+G22-I22 -> 0 | L22: =K22*M22 -> 0 | M22: =D22 | N22: =M22-D22 -> 0 | O22: =N22*I22 -> 0 | P22: =F22+H22-L22 -> 0 | S22: 0 | U22: 1 | V22: =+S22+T22+U22 -> 1
A23: 18 | B23: PUCK CHEESE | C23: JAR | F23: =E23*D23 -> 0 | G23: =SUMIF(PURCHASE!$E$3:$E$506,'INVONTERY FEB'!B23:B338,PURCHASE!$H$3:$H$506) -> 0 | H23: =SUMIF(PURCHASE!$E$3:$E$506,'INVONTERY FEB'!B23:B333,PURCHASE!$I$3:$I$506) -> 0 | I23: =ISSU!AL23 -> 0 | J23: =I23/30 -> 0 | K23: =E23+G23-I23 -> 0 | L23: =K23*M23 -> 0 | M23: =D23 | N23: =M23-D23 -> 0 | O23: =N23*I23 -> 0 | P23: =F23+H23-L23 -> 0 | Q23: K'E'H | S23: 0 | V23: =+S23+T23+U23 -> 0
A24: 19 | B24: GULCOSE LIQUID | C24: BOTT | F24: =E24*D24 -> 0 | G24: =SUMIF(PURCHASE!$E$3:$E$506,'INVONTERY FEB'!B24:B339,PURCHASE!$H$3:$H$506) -> 1 | H24: =SUMIF(PURCHASE!$E$3:$E$506,'INVONTERY FEB'!B24:B334,PURCHASE!$I$3:$I$506) -> 1750 | I24: =ISSU!AL24 -> 0 | J24: =I24/30 -> 0 | K24: =E24+G24-I24 -> 1 | L24: =K24*M24 -> 0 | M24: =D24 | N24: =M24-D24 -> 0 | O24: =N24*I24 -> 0 | P24: =F24+H24-L24 -> 1750 | S24: 0 | V24: =+S24+T24+U24 -> 0
A25: 20 | B25: POLAC MILK 390 GM | C25: TIN | D25: 0 | F25: =E25*D25 -> 0 | G25: =SUMIF(PURCHASE!$E$3:$E$506,'INVONTERY FEB'!B25:B340,PURCHASE!$H$3:$H$506) -> 96 | H25: =SUMIF(PURCHASE!$E$3:$E$506,'INVONTERY FEB'!B25:B335,PURCHASE!$I$3:$I$506) -> 25000 | I25: =ISSU!AL25 -> 42 | J25: =I25/30 -> 1.4 | K25: =E25+G25-I25 -> 54 | L25: =K25*M25 -> 0 | M25: =D25 -> 0 | N25: =M25-D25 -> 0 | O25: =N25*I25 -> 0 | P25: =F25+H25-L25 -> 25000 | V25: =+S25+T25+U25 -> 0
A26: 21 | D26: 0 | F26: =E26*D26 -> 0 | G26: =SUMIF(PURCHASE!$E$3:$E$506,'INVONTERY FEB'!B26:B341,PURCHASE!$H$3:$H$506) -> 0 | H26: =SUMIF(PURCHASE!$E$3:$E$506,'INVONTERY FEB'!B26:B336,PURCHASE!$I$3:$I$506) -> 0 | I26: =ISSU!AL26 -> 0 | J26: =I26/30 -> 0 | K26: =E26+G26-I26 -> 0 | L26: =K26*M26 -> 0 | M26: =D26 -> 0 | N26: =M26-D26 -> 0 | O26: =N26*I26 -> 0 | P26: =F26+H26-L26 -> 0 | V26: =+S26+T26+U26 -> 0
A27: 22 | D27: 0 | F27: =E27*D27 -> 0 | G27: =SUMIF(PURCHASE!$E$3:$E$506,'INVONTERY FEB'!B27:B342,PURCHASE!$H$3:$H$506) -> 0 | H27: =SUMIF(PURCHASE!$E$3:$E$506,'INVONTERY FEB'!B27:B337,PURCHASE!$I$3:$I$506) -> 0 | I27: =ISSU!AL27 -> 0 | J27: =I27/30 -> 0 | K27: =E27+G27-I27 -> 0 | L27: =K27*M27 -> 0 | M27: =D27 -> 0 | N27: =M27-D27 -> 0 | O27: =N27*I27 -> 0 | P27: =F27+H27-L27 -> 0 | V27: =+S27+T27+U27 -> 0
A28: 23 | D28: 0 | F28: =E28*D28 -> 0 | G28: =SUMIF(PURCHASE!$E$3:$E$506,'INVONTERY FEB'!B28:B333,PURCHASE!$H$3:$H$506) -> 0 | H28: =SUMIF(PURCHASE!$E$3:$E$506,'INVONTERY FEB'!B28:B333,PURCHASE!$I$3:$I$506) -> 0 | I28: =ISSU!AL28 -> 0 | J28: =I28/30 -> 0 | K28: =E28+G28-I28 -> 0 | L28: =K28*M28 -> 0 | M28: =D28 -> 0 | N28: =M28-D28 -> 0 | O28: =N28*I28 -> 0 | P28: =F28+H28-L28 -> 0 | Q28: LOCAL | V28: =+S28+T28+U28 -> 0
A29: 24 | B29: TOTA SPONAGE AMOUNT | E29: =SUM(E9:E21) -> 1495 | F29: =SUM(F6:F28) -> 577460.24 | G29: =SUM(G6:G28) -> 5553 | H29: =SUM(H6:H28) -> 519394.03 | I29: =SUM(I6:I28) -> 6221 | J29: =SUM(J6:J28) -> 222.07857 | K29: =SUM(K6:K28) -> 827 | L29: =SUM(L6:L28) -> 478047.03 | M29: =SUM(M6:M28) -> 9478.8674 | ... Q29: =SUM(Q6:Q28) -> 0 | V29: =+S29+T29+U29 -> 0
A30: 25 | B30: CAKE CRÈME | V30: =+S30+T30+U30 -> 0
A31: 26 | B31: CHOCO KNOC | C31: BUCKET | D31: 7800 | E31: 0 | F31: =E31*D31 -> 0 | G31: =SUMIF(PURCHASE!$E$3:$E$506,'INVONTERY FEB'!B31:B328,PURCHASE!$H$3:$H$506) -> 0 | H31: =SUMIF(PURCHASE!$E$3:$E$506,'INVONTERY FEB'!B31:B328,PURCHASE!$I$3:$I$506) -> 0 | I31: =ISSU!AL31 -> 0 | J31: =I31/28 -> 0 | K31: =E31+G31-I31 -> 0 | L31: =K31*M31 -> 0 | M31: =D31 -> 7800 | N31: =M31-D31 -> 0 | O31: =N31*I31 -> 0 | P31: =F31+H31-L31 -> 0 | S31: 0 | V31: =+S31+T31+U31 -> 0
A32: 27 | B32: MILK PACK CREAM200ML | C32: PCS | D32: 211 | E32: 0 | F32: =E32*D32 -> 0 | G32: =SUMIF(PURCHASE!$E$3:$E$506,'INVONTERY FEB'!B32:B328,PURCHASE!$H$3:$H$506) -> 0 | H32: =SUMIF(PURCHASE!$E$3:$E$506,'INVONTERY FEB'!B32:B328,PURCHASE!$I$3:$I$506) -> 0 | I32: =ISSU!AL32 -> 0 | J32: =I32/28 -> 0 | K32: =E32+G32-I32 -> 0 | L32: =K32*M32 -> 0 | M32: =D32 -> 211 | N32: =M32-D32 -> 0 | O32: =N32*I32 -> 0 | P32: =F32+H32-L32 -> 0 | Q32: LOCAL | S32: 0 | U32: 12 | V32: =+S32+T32+U32 -> 12
A33: 28 | B33: NESTLE BUTTER | C33: KG | D33: 1850 | E33: 0 | F33: =E33*D33 -> 0 | G33: =SUMIF(PURCHASE!$E$3:$E$506,'INVONTERY FEB'!B33:B375,PURCHASE!$H$3:$H$506) -> 40 | H33: =SUMIF(PURCHASE!$E$3:$E$506,'INVONTERY FEB'!B33:B373,PURCHASE!$I$3:$I$506) -> 74000 | I33: =ISSU!AL33 -> 15 | J33: =I33/28 -> 0.53571429 | K33: =E33+G33-I33 -> 25 | L33: =K33*M33 -> 46250 | M33: =55500/30 -> 1850 | N33: =M33-D33 -> 0 | O33: =N33*I33 -> 0 | P33: =F33+H33-L33 -> 27750 | Q33: NESTLE | S33: 10 | V33: =+S33+T33+U33 -> 10
A34: 29 | B34: WHIPPING CREAM | C34: PCS | D34: 700 | E34: 126 | F34: =E34*D34 -> 88200 | G34: =SUMIF(PURCHASE!$E$3:$E$506,'INVONTERY FEB'!B34:B328,PURCHASE!$H$3:$H$506) -> 216 | H34: =SUMIF(PURCHASE!$E$3:$E$506,'INVONTERY FEB'!B34:B328,PURCHASE!$I$3:$I$506) -> 151200 | I34: =ISSU!AL34 -> 269 | J34: =I34/28 -> 9.6071429 | K34: =E34+G34-I34 -> 73 | L34: =K34*M34 -> 51100 | M34: =168000/240 -> 700 | N34: =M34-D34 -> 0 | O34: =N34*I34 -> 0 | P34: =F34+H34-L34 -> 188300 | Q34: VENUS | V34: =+S34+T34+U34 -> 0
A35: 30 | B35: ROXELLA CRUNCHY CREAM | C35: KG | D35: 4281 | E35: 5 | F35: =E35*D35 -> 21405 | G35: =SUMIF(PURCHASE!$E$3:$E$506,'INVONTERY FEB'!B35:B328,PURCHASE!$H$3:$H$506) -> 0 | H35: =SUMIF(PURCHASE!$E$3:$E$506,'INVONTERY FEB'!B35:B328,PURCHASE!$I$3:$I$506) -> 0 | I35: =ISSU!AL35 -> 3 | J35: =I35/28 -> 0.10714286 | K35: =E35+G35-I35 -> 2 | L35: =K35*M35 -> 8562 | M35: =D35 -> 4281 | N35: =M35-D35 -> 0 | O35: =N35*I35 -> 0 | P35: =F35+H35-L35 -> 12843 | Q35: VENUS | S35: 0 | V35: =+S35+T35+U35 -> 0
A36: 31 | B36: NURPUR BUTTER | C36: KG | D36: 1800 | E36: 15 | F36: =E36*D36 -> 27000 | G36: =SUMIF(PURCHASE!$E$3:$E$506,'INVONTERY FEB'!B36:B328,PURCHASE!$H$3:$H$506) -> 10 | H36: =SUMIF(PURCHASE!$E$3:$E$506,'INVONTERY FEB'!B36:B328,PURCHASE!$I$3:$I$506) -> 19500 | I36: =ISSU!AL36 -> 25 | J36: =I36/28 -> 0.89285714 | K36: =E36+G36-I36 -> 0 | L36: =K36*M36 -> 0 | M36: =D36 -> 1800 | N36: =M36-D36 -> 0 | O36: =N36*I36 -> 0 | P36: =F36+H36-L36 -> 46500 | Q36: VENUS | S36: 0 | V36: =+S36+T36+U36 -> 0
A37: 32 | B37: CHEESE CREAM | C37: LTR | D37: 2500 | E37: 2 | F37: =E37*D37 -> 5000 | G37: =SUMIF(PURCHASE!$E$3:$E$506,'INVONTERY FEB'!B37:B329,PURCHASE!$H$3:$H$506) -> 0 | H37: =SUMIF(PURCHASE!$E$3:$E$506,'INVONTERY FEB'!B37:B329,PURCHASE!$I$3:$I$506) -> 0 | I37: =ISSU!AL37 -> 1 | J37: =I37/28 -> 0.035714286 | K37: =E37+G37-I37 -> 1 | L37: =K37*M37 -> 2500 | M37: =D37 -> 2500 | N37: =M37-D37 -> 0 | O37: =N37*I37 -> 0 | P37: =F37+H37-L37 -> 2500 | S37: 0 | T37: 12 | V37: =+S37+T37+U37 -> 12
A38: 33 | B38: G.P ICING SUGAR | C38: PCS | D38: 155 | E38: 88 | F38: =E38*D38 -> 13640 | G38: =SUMIF(PURCHASE!$E$3:$E$506,'INVONTERY FEB'!B38:B330,PURCHASE!$H$3:$H$506) -> 0 | H38: =SUMIF(PURCHASE!$E$3:$E$506,'INVONTERY FEB'!B38:B330,PURCHASE!$I$3:$I$506) -> 0 | I38: =ISSU!AL38 -> 32 | J38: =I38/28 -> 1.1428571 | K38: =E38+G38-I38 -> 56 | L38: =K38*M38 -> 8680 | M38: =D38 -> 155 | N38: =M38-D38 -> 0 | O38: =N38*I38 -> 0 | P38: =F38+H38-L38 -> 4960 | S38: =36+10 -> 46 | U38: 12 | V38: =+S38+T38+U38 -> 58
A39: 34 | B39: DARK CHOCLATE SLAB 2 KG | C39: PKT | D39: 1400 | E39: 69 | F39: =E39*D39 -> 96600 | G39: =SUMIF(PURCHASE!$E$3:$E$506,'INVONTERY FEB'!B39:B331,PURCHASE!$H$3:$H$506) -> 0 | H39: =SUMIF(PURCHASE!$E$3:$E$506,'INVONTERY FEB'!B39:B441,PURCHASE!$I$3:$I$506) -> 0 | I39: =ISSU!AL39 -> 33 | J39: =I39/28 -> 1.1785714 | K39: =E39+G39-I39 -> 36 | L39: =K39*M39 -> 50400 | M39: =D39 -> 1400 | N39: =M39-D39 -> 0 | O39: =N39*I39 -> 0 | P39: =F39+H39-L39 -> 46200 | Q39: LOCAL | S39: 20 | V39: =+S39+T39+U39 -> 20
A40: 35 | B40: MILKI CHOCLATE SLAB 2 KG | C40: PKT | D40: 1600 | E40: 65 | F40: =E40*D40 -> 104000 | G40: =SUMIF(PURCHASE!$E$3:$E$506,'INVONTERY FEB'!B40:B501,PURCHASE!$H$3:$H$506) -> 0 | H40: =SUMIF(PURCHASE!$E$3:$E$506,'INVONTERY FEB'!B40:B451,PURCHASE!$I$3:$I$506) -> 0 | I40: =ISSU!AL40 -> 26 | J40: =I40/28 -> 0.92857143 | K40: =E40+G40-I40 -> 39 | L40: =K40*M40 -> 62400 | M40: =D40 -> 1600 | N40: =M40-D40 -> 0 | O40: =N40*I40 -> 0 | P40: =F40+H40-L40 -> 41600 | Q40: REHMAT WHEAT | S40: 0 | T40: 1 | V40: =+S40+T40+U40 -> 1
A41: 36 | B41: HISS CHOCLATE 4 RINGS | C41: BOX | D41: 1500 | E41: 0 | F41: =E41*D41 -> 0 | G41: =SUMIF(PURCHASE!$E$3:$E$506,'INVONTERY FEB'!B41:B335,PURCHASE!$H$3:$H$506) -> 0 | H41: =SUMIF(PURCHASE!$E$3:$E$506,'INVONTERY FEB'!B41:B335,PURCHASE!$I$3:$I$506) -> 0 | I41: =ISSU!AL41 -> 0 | J41: =I41/28 -> 0 | K41: =E41+G41-I41 -> 0 | L41: =K41*M41 -> 0 | M41: =D41 -> 1500 | N41: =M41-D41 -> 0 | O41: =N41*I41 -> 0 | P41: =F41+H41-L41 -> 0 | Q41: VENUS | S41: 3 | V41: =+S41+T41+U41 -> 3
...

Sheet ISSU
A2: ='INVONTERY FEB'!A3 -> ID | B2: ='INVONTERY FEB'!B3 -> PRODUCT DETAIL | C2: ='INVONTERY FEB'!C3 -> UNIT | D2: ='INVONTERY FEB'!D3 -> RATE | E2: FSD FLOUR ISSU | F2: 46054 | G2: =1+F2 -> 46055 | H2: =1+G2 -> 46056 | I2: =1+H2 -> 46057 | J2: =1+I2 -> 46058 | K2: =1+J2 -> 46059 | L2: =1+K2 -> 46060 | M2: =1+L2 -> 46061 | N2: =1+M2 -> 46062 | ... AJ2: =1+AI2 -> 46084 | AK2: STOCK ON FLOUR | AL2: TOTAL | AM2: AVERAGE USAGE
A5: ='INVONTERY FEB'!A5 -> 1.1 | B5: ='INVONTERY FEB'!B5 -> SPONAGE | C5: ='INVONTERY FEB'!C5 | D5: ='INVONTERY FEB'!D5 | AL5: =SUM(E5:AK5) -> 0 | AM5: =AVERAGE(E5:AL5) -> 0
A6: ='INVONTERY FEB'!A6 -> 1 | B6: ='INVONTERY FEB'!B6 -> RED VELVET CONCENTRATE 10 KG | C6: ='INVONTERY FEB'!C6 -> KG | D6: ='INVONTERY FEB'!D6 | AL6: =SUM(E6:AK6) -> 0 | AM6: =AVERAGE(E6:AL6) -> 0
A7: ='INVONTERY FEB'!A7 -> 2 | B7: ='INVONTERY FEB'!B7 -> LA OLA CONCENTRATE | C7: ='INVONTERY FEB'!C7 -> KG | D7: ='INVONTERY FEB'!D7 | AL7: =SUM(E7:AK7) -> 0 | AM7: =AVERAGE(E7:AL7) -> 0
A8: ='INVONTERY FEB'!A8 -> 3 | B8: ='INVONTERY FEB'!B8 -> AUSTRIA SPONGE MIX CONCENTRATE (269) | C8: ='INVONTERY FEB'!C8 -> KG | D8: ='INVONTERY FEB'!D8 | AL8: =SUM(E8:AK8) -> 0 | AM8: =AVERAGE(E8:AL8) -> 0
A9: ='INVONTERY FEB'!A9 -> 4 | B9: ='INVONTERY FEB'!B9 -> KISAN CANOLA OIL 5 LTR | C9: ='INVONTERY FEB'!C9 -> BOX | D9: ='INVONTERY FEB'!D9 -> 560 | F9: 5 | I9: 2 | J9: 10 | K9: 15 | L9: 10 | N9: 10 | Q9: 5 | R9: 15 | S9: 10 | U9: 13 | V9: 10 | W9: 5 | X9: 5 | Y9: 10 | Z9: 5 | AB9: 10 | AD9: 10 | AE9: 5 | AF9: 5 | AG9: 10 | AL9: =SUM(E9:AK9) -> 170 | AM9: =AVERAGE(E9:AL9) -> 16.190476
A10: ='INVONTERY FEB'!A10 -> 5 | B10: ='INVONTERY FEB'!B10 -> FLOUR | C10: ='INVONTERY FEB'!C10 -> BAG | D10: ='INVONTERY FEB'!D10 -> 134 | F10: 50 | K10: 50 | Q10: 50 | U10: 50 | AF10: 50 | AL10: =SUM(E10:AK10) -> 250 | AM10: =AVERAGE(E10:AL10) -> 83.333333 | AO10: =9296-9325 -> -29
A11: ='INVONTERY FEB'!A11 -> 6 | B11: ='INVONTERY FEB'!B11 -> LOSSE SUGAR 50KG | C11: ='INVONTERY FEB'!C11 -> KG | D11: ='INVONTERY FEB'!D11 -> 184 | J11: 50 | N11: 50 | R11: 50 | V11: 50 | AE11: 50 | AF11: 50 | AL11: =SUM(E11:AK11) -> 300 | AM11: =AVERAGE(E11:AL11) -> 85.714286
A12: ='INVONTERY FEB'!A12 -> 7 | B12: ='INVONTERY FEB'!B12 -> EGGS | C12: ='INVONTERY FEB'!C12 -> PCS | D12: ='INVONTERY FEB'!D12 -> 31.66875 | F12: 200 | G12: 200 | H12: 0 | I12: 200 | J12: 370 | K12: 300 | L12: 200 | M12: 300 | N12: 270 | O12: 100 | P12: 200 | Q12: 200 | R12: 500 | S12: 470 | U12: 200 | V12: 300 | X12: 260 | Z12: 200 | AA12: 100 | AB12: 200 | AE12: 100 | AF12: 100 | AG12: 200 | AL12: =SUM(E12:AK12) -> 5170 | AM12: =AVERAGE(E12:AL12) -> 430.83333
A13: ='INVONTERY FEB'!A13 -> 8 | B13: ='INVONTERY FEB'!B13 -> POLAC CONDENSED MILK 1-LTR | C13: ='INVONTERY FEB'!C13 -> TIN | D13: ='INVONTERY FEB'!D13 -> 625 | F13: 4 | G13: 2 | H13: 2 | I13: 1 | L13: 3 | M13: 4 | N13: 4 | O13: 2 | P13: 3 | Q13: 3 | R13: 4 | S13: 5 | T13: 3 | U13: 3 | V13: 3 | AB13: 4 | AE13: 3 | AF13: 1 | AL13: =SUM(E13:AK13) -> 54 | AM13: =AVERAGE(E13:AL13) -> 5.6842105
A14: ='INVONTERY FEB'!A14 -> 9 | B14: ='INVONTERY FEB'!B14 -> OLPERS MILK 1.5 LTR | C14: ='INVONTERY FEB'!C14 -> PCS | D14: ='INVONTERY FEB'!D14 -> 488.1129 | F14: 8 | H14: 8 | I14: 8 | J14: 8 | K14: 16 | L14: 8 | N14: 8 | O14: 3 | Q14: 9 | R14: 16 | S14: 8 | U14: 8 | V14: 8 | W14: 8 | X14: 8 | Z14: 8 | AB14: 8 | AC14: 16 | AE14: 10 | AG14: 8 | AH14: 8 | AL14: =SUM(E14:AK14) -> 190 | AM14: =AVERAGE(E14:AL14) -> 17.272727
A15: ='INVONTERY FEB'!A15 -> 10 | B15: ='INVONTERY FEB'!B15 -> COCO POWDER MALASIAN | C15: ='INVONTERY FEB'!C15 -> KG | D15: ='INVONTERY FEB'!D15 -> 3917.0857 | F15: 2 | H15: 2 | I15: 2 | K15: 4 | L15: 2 | N15: 2 | O15: 2 | P15: 2 | Q15: 2 | R15: 3 | S15: 2 | U15: 2 | X15: 3 | AA15: 3 | AE15: 2 | AG15: 2 | AL15: =SUM(E15:AK15) -> 37 | AM15: =AVERAGE(E15:AL15) -> 4.3529412
A16: ='INVONTERY FEB'!A16 -> 11 | B16: ='INVONTERY FEB'!B16 -> VANILLA ESSENCE 500 GM | C16: ='INVONTERY FEB'!C16 -> BOTT | D16: ='INVONTERY FEB'!D16 -> 1150 | O16: 1 | V16: 1 | Y16: 1 | AE16: 2 | AL16: =SUM(E16:AK16) -> 5 | AM16: =AVERAGE(E16:AL16) -> 2
A17: ='INVONTERY FEB'!A17 -> 12 | B17: ='INVONTERY FEB'!B17 -> SALT 800GM | C17: ='INVONTERY FEB'!C17 -> PKT | D17: ='INVONTERY FEB'!D17 -> 29 | AL17: =SUM(E17:AK17) -> 0 | AM17: =AVERAGE(E17:AL17) -> 0
A18: ='INVONTERY FEB'!A18 -> 13 | B18: ='INVONTERY FEB'!B19 -> BAKING SODA 1- KG | C18: ='INVONTERY FEB'!C19 -> KG | D18: ='INVONTERY FEB'!D19 -> 160 | AL18: =SUM(E18:AK18) -> 0 | AM18: =AVERAGE(E18:AL18) -> 0
A19: ='INVONTERY FEB'!A19 -> 14 | B19: ='INVONTERY FEB'!B18 -> BAKING POWDER HOLIDAY | C19: ='INVONTERY FEB'!C18 -> KG | D19: ='INVONTERY FEB'!D18 -> 2000 | J19: 1 | Q19: 1 | Y19: 1 | AL19: =SUM(E19:AK19) -> 3 | AM19: =AVERAGE(E19:AL19) -> 1.5
A20: ='INVONTERY FEB'!A20 -> 15 | B20: ='INVONTERY FEB'!B20 -> STARCH | C20: ='INVONTERY FEB'!C20 -> KG | D20: ='INVONTERY FEB'!D20 -> 200 | AL20: =SUM(E20:AK20) -> 0 | AM20: =AVERAGE(E20:AL20) -> 0
A21: ='INVONTERY FEB'!A21 -> 16 | B21: ='INVONTERY FEB'!B21 -> KHOYA ESSANSE | C21: ='INVONTERY FEB'!C21 -> PCS | D21: ='INVONTERY FEB'!D21 | AL21: =SUM(E21:AK21) -> 0 | AM21: =AVERAGE(E21:AL21) -> 0
A22: ='INVONTERY FEB'!A22 -> 17 | B22: ='INVONTERY FEB'!B22 -> HABIB OIL 4.5 L BOT | C22: ='INVONTERY FEB'!C22 -> BOTT | D22: ='INVONTERY FEB'!D22 | AL22: =SUM(E22:AK22) -> 0 | AM22: =AVERAGE(E22:AL22) -> 0
A23: ='INVONTERY FEB'!A23 -> 18 | B23: ='INVONTERY FEB'!B23 -> PUCK CHEESE | C23: ='INVONTERY FEB'!C23 -> JAR | D23: ='INVONTERY FEB'!D23 | AL23: =SUM(E23:AK23) -> 0 | AM23: =AVERAGE(E23:AL23) -> 0
A24: ='INVONTERY FEB'!A24 -> 19 | B24: ='INVONTERY FEB'!B24 -> GULCOSE LIQUID | C24: ='INVONTERY FEB'!C24 -> BOTT | D24: ='INVONTERY FEB'!D24 | AL24: =SUM(E24:AK24) -> 0 | AM24: =AVERAGE(E24:AL24) -> 0
A25: ='INVONTERY FEB'!A25 -> 20 | B25: ='INVONTERY FEB'!B25 -> POLAC MILK 390 GM | C25: ='INVONTERY FEB'!C25 -> TIN | D25: ='INVONTERY FEB'!D25 -> 0 | H25: 2 | L25: 10 | W25: 9 | X25: 2 | Y25: 10 | AA25: 3 | AG25: 6 | AL25: =SUM(E25:AK25) -> 42 | AM25: =AVERAGE(E25:AL25) -> 10.5
A26: ='INVONTERY FEB'!A26 -> 21 | B26: ='INVONTERY FEB'!B26 | C26: ='INVONTERY FEB'!C26 | D26: ='INVONTERY FEB'!D26 -> 0 | AL26: =SUM(E26:AK26) -> 0 | AM26: =AVERAGE(E26:AL26) -> 0
A27: ='INVONTERY FEB'!A27 -> 22 | B27: ='INVONTERY FEB'!B27 | C27: ='INVONTERY FEB'!C27 | D27: ='INVONTERY FEB'!D27 -> 0 | AL27: =SUM(E27:AK27) -> 0 | AM27: =AVERAGE(E27:AL27) -> 0
A28: ='INVONTERY FEB'!A28 -> 23 | B28: ='INVONTERY FEB'!B28 | C28: ='INVONTERY FEB'!C28 | D28: ='INVONTERY FEB'!D28 -> 0 | AL28: =SUM(E28:AK28) -> 0 | AM28: =AVERAGE(E28:AL28) -> 0
A29: ='INVONTERY FEB'!A29 -> 24 | B29: ='INVONTERY FEB'!B29 -> TOTA SPONAGE AMOUNT | C29: ='INVONTERY FEB'!C29 | D29: ='INVONTERY FEB'!D29 | AL29: =SUM(E29:AK29) -> 0 | AM29: =AVERAGE(E29:AL29) -> 0
A30: ='INVONTERY FEB'!A30 -> 25 | B30: ='INVONTERY FEB'!B30 -> CAKE CRÈME | C30: ='INVONTERY FEB'!C30 | D30: ='INVONTERY FEB'!D30 | AL30: =SUM(E30:AK30) -> 0 | AM30: =AVERAGE(E30:AL30) -> 0
A31: ='INVONTERY FEB'!A31 -> 26 | B31: ='INVONTERY FEB'!B31 -> CHOCO KNOC | C31: ='INVONTERY FEB'!C31 -> BUCKET | D31: ='INVONTERY FEB'!D31 -> 7800 | AL31: =SUM(E31:AK31) -> 0 | AM31: =AVERAGE(E31:AL31) -> 0
A32: ='INVONTERY FEB'!A32 -> 27 | B32: ='INVONTERY FEB'!B32 -> MILK PACK CREAM200ML | C32: ='INVONTERY FEB'!C32 -> PCS | D32: ='INVONTERY FEB'!D32 -> 211 | AL32: =SUM(E32:AK32) -> 0 | AM32: =AVERAGE(E32:AL32) -> 0
A33: ='INVONTERY FEB'!A33 -> 28 | B33: ='INVONTERY FEB'!B33 -> NESTLE BUTTER | C33: ='INVONTERY FEB'!C33 -> KG | D33: ='INVONTERY FEB'!D33 -> 1850 | M33: 10 | S33: 5 | AL33: =SUM(E33:AK33) -> 15 | AM33: =AVERAGE(E33:AL33) -> 10
A34: ='INVONTERY FEB'!A34 -> 29 | B34: ='INVONTERY FEB'!B34 -> WHIPPING CREAM | C34: ='INVONTERY FEB'!C34 -> PCS | D34: ='INVONTERY FEB'!D34 -> 700 | F34: 12 | G34: 9 | H34: 8 | I34: 10 | J34: 11 | K34: 11 | L34: 10 | M34: 13 | N34: 13 | O34: 13 | P34: 10 | Q34: 9 | R34: 15 | S34: 18 | T34: 12 | U34: 12 | V34: 14 | W34: 7 | X34: 10 | Y34: 10 | Z34: 0 | AA34: 10 | AB34: 6 | AE34: 13 | AF34: 6 | AG34: 7 | AL34: =SUM(E34:AK34) -> 269 | AM34: =AVERAGE(E34:AL34) -> 19.925926
A35: ='INVONTERY FEB'!A35 -> 30 | B35: ='INVONTERY FEB'!B35 -> ROXELLA CRUNCHY CREAM | C35: ='INVONTERY FEB'!C35 -> KG | D35: ='INVONTERY FEB'!D35 -> 4281 | F35: 1 | K35: 1 | N35: 1 | AL35: =SUM(E35:AK35) -> 3 | AM35: =AVERAGE(E35:AL35) -> 1.5
A36: ='INVONTERY FEB'!A36 -> 31 | B36: ='INVONTERY FEB'!B36 -> NURPUR BUTTER | C36: ='INVONTERY FEB'!C36 -> KG | D36: ='INVONTERY FEB'!D36 -> 1800 | F36: 10 | M36: 15 | O36: 0 | AL36: =SUM(E36:AK36) -> 25 | AM36: =AVERAGE(E36:AL36) -> 12.5
A37: ='INVONTERY FEB'!A37 -> 32 | B37: ='INVONTERY FEB'!B37 -> CHEESE CREAM | C37: ='INVONTERY FEB'!C37 -> LTR | D37: ='INVONTERY FEB'!D37 -> 2500 | J37: 1 | AL37: =SUM(E37:AK37) -> 1 | AM37: =AVERAGE(E37:AL37) -> 1
A38: ='INVONTERY FEB'!A38 -> 33 | B38: ='INVONTERY FEB'!B38 -> G.P ICING SUGAR | C38: ='INVONTERY FEB'!C38 -> PCS | D38: ='INVONTERY FEB'!D38 -> 155 | S38: 10 | W38: 10 | AC38: 10 | AG38: 2 | AL38: =SUM(E38:AK38) -> 32 | AM38: =AVERAGE(E38:AL38) -> 12.8
A39: ='INVONTERY FEB'!A39 -> 34 | B39: ='INVONTERY FEB'!B39 -> DARK CHOCLATE SLAB 2 KG | C39: ='INVONTERY FEB'!C39 -> PKT | D39: ='INVONTERY FEB'!D39 -> 1400 | F39: 3 | J39: 3 | K39: 4 | N39: 3 | O39: 3 | P39: 2 | R39: 3 | S39: 3 | U39: 3 | AA39: 3 | AF39: 3 | AL39: =SUM(E39:AK39) -> 33 | AM39: =AVERAGE(E39:AL39) -> 5.5
A40: ='INVONTERY FEB'!A40 -> 35 | B40: ='INVONTERY FEB'!B40 -> MILKI CHOCLATE SLAB 2 KG | C40: ='INVONTERY FEB'!C40 -> PKT | D40: ='INVONTERY FEB'!D40 -> 1600 | H40: 2 | K40: 2 | N40: 5 | P40: 5 | R40: 2 | S40: 2 | U40: 2 | Y40: 2 | AB40: 2 | AG40: 2 | AL40: =SUM(E40:AK40) -> 26 | AM40: =AVERAGE(E40:AL40) -> 4.7272727
A41: ='INVONTERY FEB'!A41 -> 36 | B41: ='INVONTERY FEB'!B41 -> HISS CHOCLATE 4 RINGS | C41: ='INVONTERY FEB'!C41 -> BOX | D41: ='INVONTERY FEB'!D41 -> 1500 | AL41: =SUM(E41:AK41) -> 0 | AM41: =AVERAGE(E41:AL41) -> 0
A42: ='INVONTERY FEB'!A42 -> 37 | B42: ='INVONTERY FEB'!B42 -> HISS CHOCLATE 2 RINGS | C42: ='INVONTERY FEB'!C42 -> BOX | D42: ='INVONTERY FEB'!D42 -> 667 | F42: 2 | I42: 1 | K42: 2 | N42: 2 | S42: 1 | V42: 1 | W42: 1 | AA42: 1 | AC42: 3 | AG42: 1 | AL42: =SUM(E42:AK42) -> 15 | AM42: =AVERAGE(E42:AL42) -> 2.7272727
A43: ='INVONTERY FEB'!A43 -> 38 | B43: ='INVONTERY FEB'!B43 -> DAIRY MILK | C43: ='INVONTERY FEB'!C43 -> BOX | D43: ='INVONTERY FEB'!D43 -> 433.30435 | H43: 3 | I43: 2 | K43: 3 | N43: 1 | P43: 1 | S43: 2 | V43: 3 | Z43: 3 | AE43: 3 | AG43: 2 | AL43: =SUM(E43:AK43) -> 23 | AM43: =AVERAGE(E43:AL43) -> 4.1818182
...

Sheet DAILY UPDATE
B1: C-1 (KOHINOOR) | S1: C-2 (SUSAN ROAD) | AJ1: C-5 (GULBERG) | BB1: TOTAL | BW1: DAILY CASH RECIVED | BX1: HOLD CASH | BY1: PHYSICIAL CASH IN HAND
B2: C/C | D2: CAKES | G2: PAS | H2: LAV | I2: CUPCAKE | K2: SUN | L2: 3 MILK | M2: C.B | N2: BRO | O2: DIM | P2: TOTAL | Q2: CASH | R2: CASH | S2: C/C | U2: CAKES | X2: PAS | Y2: LAV | Z2: CUPCAKE | AB2: SUN | AC2: 3 MILK | AD2: C.B | AE2: BRO | AF2: DIMI | AG2: TOTAL | AH2: CASH | AI2: CASH | AJ2: C/C | AM2: CAKES | AP2: PAS | AQ2: LAV | AR2: CUPCAKE | AT2: SUN | AU2: 3 MILKI | AV2: C.B | AW2: BRO | AX2: DIME | AY2: TOTAL | AZ2: CASH | BA2: CASH | BB2: C/C | BD2: FSD CAKES | BG2: PAS | BH2: LAV | BI2: CUPCAKE | BK2: SUN | BL2: T.M.S | BM2: C.B | BN2: BRO | BO2: DIMI | BP2: DATE | BQ2: OPENING | BR2: DAILY | BS2: TOTAL | BT2: DAILY | BU2: CLOSING
A3: DATE | B3: QTY | C3: PND | D3: CT-1 | E3: CT-2 | F3: CT-3 | G3: 250 | H3: CAK | I3: REG | J3: CUS | P3: SALE | Q3: REC. | R3: BAL | S3: QTY | T3: PND | U3: CT-1 | V3: CT-2 | W3: CT-3 | X3: 250 | Y3: CAK | Z3: REG | AA3: CUS | AF3: DMI | AG3: SALE | AH3: REC. | AI3: BAL | AJ3: QTY | AK3: PND | AL3: C.2.P | AM3: CT-1 | AN3: CT-2 | AO3: CT-3 | AP3: 250 | AQ3: CAK | AR3: REG | AS3: CUS | AY3: SALE | AZ3: REC. | BA3: BAL | BB3: QTY | BC3: PND | BD3: CT-1 | BE3: CT-2 | BF3: CT-3 | BG3: 225 | BH3: CAK | BI3: REG | BJ3: CUS | BQ3: BAL | BR3: SALE | BT3: EXPENSE | BU3: BAL | CA3: =NOW() -> 46167.182
B4: 1100 | D4: 1499 | E4: 1699 | F4: 1899 | G4: 250 | H4: 275 | I4: 220 | J4: 320 | K4: 220 | L4: 450 | M4: 120 | N4: 275 | O4: 1000 | S4: 1100 | U4: 1499 | V4: 1699 | W4: 1899 | X4: 250 | Y4: 275 | Z4: 220 | AA4: 320 | AB4: 220 | AC4: 450 | AD4: 120 | AE4: 275 | AF4: 1000 | AJ4: 1100 | AL4: 2399 | AM4: 1499 | AN4: 1699 | AO4: 1899 | AP4: 250 | AQ4: 275 | AR4: 220 | AS4: 320 | AT4: 220 | AU4: 450 | AV4: 120 | AW4: 275 | AX4: 1000 | CA4: BAKERY SAFE DETAIL
A5: 46054 | B5: 1 | C5: 3 | D5: 5 | E5: 4 | F5: =14+7 -> 21 | H5: 5 | K5: 6 | L5: 10 | M5: 10 | P5: =C5*$B$4+D5*$D$4+E5*$E$4+F5*$F$4+G5*$G$4+H5*$H$4+I5*$I$4+J5*$J$4+K5*$K$4+L5*$L$4+M5*$M$4+N5*$N$4+O5*$O$4 -> 65865 | Q5: 65865 | R5: =+R4+P5-Q5 -> 0 | S5: 2 | T5: 30 | U5: 3 | V5: 1 | W5: 6 | Y5: 1 | Z5: 6 | AB5: 5 | AC5: 5 | AD5: 5 | AG5: =T5*$B$4+U5*$D$4+V5*$E$4+W5*$F$4+X5*$G$4+Y5*$H$4+Z5*$I$4+AA5*$J$4+AB5*$K$4+AC5*$L$4+AD5*$M$4+AE5*$N$4+AF5*$O$4 -> 56135 | AH5: 56135 | AI5: =+AI4+AG5-AH5 -> 0 | AJ5: 2 | AK5: 11 | AM5: 3 | AN5: 1 | AO5: 7 | AQ5: 3 | AT5: 10 | AU5: 10 | AV5: 5 | AY5: =AK5*$AJ$4+AM5*$AM$4+AN5*$AN$4+AO5*$AO$4+AP5*$AP$4+AQ5*$AQ$4+AR5*$AR$4+AS5*$AS$4+AT5*$AT$4+AU5*$AU$4+AV5*$AV$4+AW5*$AW$4+AX5*$AX$4+$AL$4*AL5 -> 39714 | AZ5: 39714 | BA5: =+BA4+AY5-AZ5 -> 0 | BB5: =B5+S5+AJ5 -> 5 | BC5: =C5+T5+AK5 -> 44 | BD5: =D5+U5+AM5 -> 11 | BE5: =E5+V5+AN5 -> 6 | BF5: =F5+W5+AO5 -> 34 | BG5: =G5+X5+AP5 -> 0 | BH5: =H5+Y5+AQ5 -> 9 | BI5: =I5+Z5+AR5 -> 6 | BJ5: =J5+AA5+AS5 -> 0 | BK5: =K5+AB5+AT5 -> 21 | ... BO5: =O5+AF5+AX5 -> 0 | BP5: =A5 -> 46054 | BQ5: 420 | BR5: =AY5+AG5+P5 -> 161714 | BS5: =BR5+BQ5 -> 162134 | BT5: 0 | BU5: =BS5-BT5 -> 162134 | BW5: =Q5+AH5+AZ5 -> 161714 | BX5: =R5+AI5+BA5 -> 0 | BY5: =+BU5-BX5 -> 162134 | CA5: 5000 | CC5: =+CB5*CA5 -> 0
A6: =1+A5 -> 46055 | D6: 1 | E6: 1 | F6: 9 | K6: 5 | L6: 10 | P6: =C6*$B$4+D6*$D$4+E6*$E$4+F6*$F$4+G6*$G$4+H6*$H$4+I6*$I$4+J6*$J$4+K6*$K$4+L6*$L$4+M6*$M$4+N6*$N$4+O6*$O$4 -> 25889 | R6: =+R5+P6-Q6 -> 25889 | U6: 1 | V6: 1 | W6: 3 | Y6: 1 | AC6: 5 | AD6: 15 | AG6: =T6*$B$4+U6*$D$4+V6*$E$4+W6*$F$4+X6*$G$4+Y6*$H$4+Z6*$I$4+AA6*$J$4+AB6*$K$4+AC6*$L$4+AD6*$M$4+AE6*$N$4+AF6*$O$4 -> 13220 | AH6: 13220 | AI6: =+AI5+AG6-AH6 -> 0 | AJ6: 2 | AK6: 7 | AM6: 3 | AN6: 1 | AO6: 10 | AQ6: 3 | AT6: 5 | AU6: 10 | AW6: 20 | AY6: =AK6*$AJ$4+AM6*$AM$4+AN6*$AN$4+AO6*$AO$4+AP6*$AP$4+AQ6*$AQ$4+AR6*$AR$4+AS6*$AS$4+AT6*$AT$4+AU6*$AU$4+AV6*$AV$4+AW6*$AW$4+AX6*$AX$4+$AL$4*AL6 -> 44811 | AZ6: 44811 | BA6: =+BA5+AY6-AZ6 -> 0 | BB6: =B6+S6+AJ6 -> 2 | BC6: =C6+T6+AK6 -> 7 | BD6: =D6+U6+AM6 -> 5 | BE6: =E6+V6+AN6 -> 3 | BF6: =F6+W6+AO6 -> 22 | BG6: =G6+X6+AP6 -> 0 | BH6: =H6+Y6+AQ6 -> 4 | BI6: =I6+Z6+AR6 -> 0 | BJ6: =J6+AA6+AS6 -> 0 | BK6: =K6+AB6+AT6 -> 10 | ... BO6: =O6+AF6+AX6 -> 0 | BP6: =A6 -> 46055 | BQ6: =BU5 -> 162134 | BR6: =AY6+AG6+P6 -> 83920 | BS6: =BR6+BQ6 -> 246054 | BT6: 0 | BU6: =BS6-BT6 -> 246054 | BW6: =Q6+AH6+AZ6 -> 58031 | BX6: =R6+AI6+BA6 -> 25889 | BY6: =+BU6-BX6 -> 220165 | CA6: 1000 | CC6: =+CB6*CA6 -> 0
A7: =1+A6 -> 46056 | B7: 1 | C7: 5 | D7: 5 | E7: 3 | F7: 14 | I7: 3 | K7: 5 | L7: 10 | M7: 5 | N7: 20 | P7: =C7*$B$4+D7*$D$4+E7*$E$4+F7*$F$4+G7*$G$4+H7*$H$4+I7*$I$4+J7*$J$4+K7*$K$4+L7*$L$4+M7*$M$4+N7*$N$4+O7*$O$4 -> 57038 | R7: =+R6+P7-Q7 -> 82927 | U7: 2 | W7: 6 | Y7: 5 | Z7: 6 | AB7: 6 | AC7: 3 | AG7: =T7*$B$4+U7*$D$4+V7*$E$4+W7*$F$4+X7*$G$4+Y7*$H$4+Z7*$I$4+AA7*$J$4+AB7*$K$4+AC7*$L$4+AD7*$M$4+AE7*$N$4+AF7*$O$4 -> 19757 | AH7: 19757 | AI7: =+AI6+AG7-AH7 -> 0 | AJ7: 1 | AK7: 3 | AM7: 1 | AN7: 2 | AO7: 7 | AU7: 5 | AV7: 5 | AY7: =AK7*$AJ$4+AM7*$AM$4+AN7*$AN$4+AO7*$AO$4+AP7*$AP$4+AQ7*$AQ$4+AR7*$AR$4+AS7*$AS$4+AT7*$AT$4+AU7*$AU$4+AV7*$AV$4+AW7*$AW$4+AX7*$AX$4+$AL$4*AL7 -> 24340 | AZ7: 24340 | BA7: =+BA6+AY7-AZ7 -> 0 | BB7: =B7+S7+AJ7 -> 2 | BC7: =C7+T7+AK7 -> 8 | BD7: =D7+U7+AM7 -> 8 | BE7: =E7+V7+AN7 -> 5 | BF7: =F7+W7+AO7 -> 27 | BG7: =G7+X7+AP7 -> 0 | BH7: =H7+Y7+AQ7 -> 5 | BI7: =I7+Z7+AR7 -> 9 | BJ7: =J7+AA7+AS7 -> 0 | BK7: =K7+AB7+AT7 -> 11 | ... BO7: =O7+AF7+AX7 -> 0 | BP7: =A7 -> 46056 | BQ7: =BU6 -> 246054 | BR7: =AY7+AG7+P7 -> 101135 | BS7: =BR7+BQ7 -> 347189 | BT7: 0 | BU7: =BS7-BT7 -> 347189 | BW7: =Q7+AH7+AZ7 -> 44097 | BX7: =R7+AI7+BA7 -> 82927 | BY7: =+BU7-BX7 -> 264262 | CA7: 500 | CC7: =+CB7*CA7 -> 0
A8: =1+A7 -> 46057 | D8: 4 | E8: 2 | F8: 14 | H8: 9 | K8: 3 | L8: 10 | M8: 9 | P8: =C8*$B$4+D8*$D$4+E8*$E$4+F8*$F$4+G8*$G$4+H8*$H$4+I8*$I$4+J8*$J$4+K8*$K$4+L8*$L$4+M8*$M$4+N8*$N$4+O8*$O$4 -> 44695 | Q8: 127622 | R8: =+R7+P8-Q8 -> 0 | S8: 1 | T8: 2 | U8: 1 | V8: 2 | W8: 5 | Y8: 2 | AC8: 4 | AG8: =T8*$B$4+U8*$D$4+V8*$E$4+W8*$F$4+X8*$G$4+Y8*$H$4+Z8*$I$4+AA8*$J$4+AB8*$K$4+AC8*$L$4+AD8*$M$4+AE8*$N$4+AF8*$O$4 -> 18942 | AI8: =+AI7+AG8-AH8 -> 18942 | AM8: 2 | AN8: 0 | AO8: 6 | AQ8: 7 | AR8: 5 | AS8: 0 | AT8: 4 | AU8: 10 | AV8: 5 | AW8: 20 | AY8: =AK8*$AJ$4+AM8*$AM$4+AN8*$AN$4+AO8*$AO$4+AP8*$AP$4+AQ8*$AQ$4+AR8*$AR$4+AS8*$AS$4+AT8*$AT$4+AU8*$AU$4+AV8*$AV$4+AW8*$AW$4+AX8*$AX$4+$AL$4*AL8 -> 28897 | AZ8: 28897 | BA8: =+BA7+AY8-AZ8 -> 0 | BB8: =B8+S8+AJ8 -> 1 | BC8: =C8+T8+AK8 -> 2 | BD8: =D8+U8+AM8 -> 7 | BE8: =E8+V8+AN8 -> 4 | BF8: =F8+W8+AO8 -> 25 | BG8: =G8+X8+AP8 -> 0 | BH8: =H8+Y8+AQ8 -> 18 | BI8: =I8+Z8+AR8 -> 5 | BJ8: =J8+AA8+AS8 -> 0 | BK8: =K8+AB8+AT8 -> 7 | ... BO8: =O8+AF8+AX8 -> 0 | BP8: =A8 -> 46057 | BQ8: =BU7 -> 347189 | BR8: =AY8+AG8+P8 -> 92534 | BS8: =BR8+BQ8 -> 439723 | BT8: 96875 | BU8: =BS8-BT8 -> 342848 | BW8: =Q8+AH8+AZ8 -> 156519 | BX8: =R8+AI8+BA8 -> 18942 | BY8: =+BU8-BX8 -> 323906 | CA8: 100 | CC8: =+CB8*CA8 -> 0
A9: =1+A8 -> 46058 | D9: 4 | E9: 3 | F9: 18 | H9: 10 | K9: 5 | L9: 10 | M9: 9 | N9: 19 | P9: =C9*$B$4+D9*$D$4+E9*$E$4+F9*$F$4+G9*$G$4+H9*$H$4+I9*$I$4+J9*$J$4+K9*$K$4+L9*$L$4+M9*$M$4+N9*$N$4+O9*$O$4 -> 59930 | R9: =+R8+P9-Q9 -> 59930 | U9: 2 | W9: 5 | Y9: 1 | AB9: 6 | AC9: 5 | AD9: 10 | AG9: =T9*$B$4+U9*$D$4+V9*$E$4+W9*$F$4+X9*$G$4+Y9*$H$4+Z9*$I$4+AA9*$J$4+AB9*$K$4+AC9*$L$4+AD9*$M$4+AE9*$N$4+AF9*$O$4 -> 17538 | AH9: 36480 | AI9: =+AI8+AG9-AH9 -> 0 | AJ9: 1 | AK9: 5 | AM9: 3 | AN9: 2 | AO9: 14 | AQ9: 4 | AT9: 11 | AU9: 7 | AV9: 10 | AY9: =AK9*$AJ$4+AM9*$AM$4+AN9*$AN$4+AO9*$AO$4+AP9*$AP$4+AQ9*$AQ$4+AR9*$AR$4+AS9*$AS$4+AT9*$AT$4+AU9*$AU$4+AV9*$AV$4+AW9*$AW$4+AX9*$AX$4+$AL$4*AL9 -> 47851 | AZ9: 47851 | BA9: =+BA8+AY9-AZ9 -> 0 | BB9: =B9+S9+AJ9 -> 1 | BC9: =C9+T9+AK9 -> 5 | BD9: =D9+U9+AM9 -> 9 | BE9: =E9+V9+AN9 -> 5 | BF9: =F9+W9+AO9 -> 37 | BG9: =G9+X9+AP9 -> 0 | BH9: =H9+Y9+AQ9 -> 15 | BI9: =I9+Z9+AR9 -> 0 | BJ9: =J9+AA9+AS9 -> 0 | BK9: =K9+AB9+AT9 -> 22 | ... BO9: =O9+AF9+AX9 -> 0 | BP9: =A9 -> 46058 | BQ9: =BU8 -> 342848 | BR9: =AY9+AG9+P9 -> 125319 | BS9: =BR9+BQ9 -> 468167 | BT9: 0 | BU9: =BS9-BT9 -> 468167 | BW9: =Q9+AH9+AZ9 -> 84331 | BX9: =R9+AI9+BA9 -> 59930 | BY9: =+BU9-BX9 -> 408237 | CA9: 50 | CC9: =+CB9*CA9 -> 0
A10: =1+A9 -> 46059 | B10: 2 | C10: 9 | D10: 4 | E10: 4 | F10: 25 | H10: 10 | I10: 3 | K10: 5 | L10: 15 | M10: 10 | N10: 20 | P10: =C10*$B$4+D10*$D$4+E10*$E$4+F10*$F$4+G10*$G$4+H10*$H$4+I10*$I$4+J10*$J$4+K10*$K$4+L10*$L$4+M10*$M$4+N10*$N$4+O10*$O$4 -> 88127 | R10: =+R9+P10-Q10 -> 148057 | U10: 2 | V10: 1 | W10: 6 | Z10: 4 | AC10: 5 | AD10: 7 | AG10: =T10*$B$4+U10*$D$4+V10*$E$4+W10*$F$4+X10*$G$4+Y10*$H$4+Z10*$I$4+AA10*$J$4+AB10*$K$4+AC10*$L$4+AD10*$M$4+AE10*$N$4+AF10*$O$4 -> 20061 | AH10: 20061 | AI10: =+AI9+AG10-AH10 -> 0 | AJ10: 2 | AK10: 9 | AM10: 4 | AN10: 3 | AO10: 15 | AT10: 7 | AU10: 10 | AV10: 10 | AY10: =AK10*$AJ$4+AM10*$AM$4+AN10*$AN$4+AO10*$AO$4+AP10*$AP$4+AQ10*$AQ$4+AR10*$AR$4+AS10*$AS$4+AT10*$AT$4+AU10*$AU$4+AV10*$AV$4+AW10*$AW$4+AX10*$AX$4+$AL$4*AL10 -> 56718 | AZ10: 56718 | BA10: =+BA9+AY10-AZ10 -> 0 | BB10: =B10+S10+AJ10 -> 4 | BC10: =C10+T10+AK10 -> 18 | BD10: =D10+U10+AM10 -> 10 | BE10: =E10+V10+AN10 -> 8 | BF10: =F10+W10+AO10 -> 46 | BG10: =G10+X10+AP10 -> 0 | BH10: =H10+Y10+AQ10 -> 10 | BI10: =I10+Z10+AR10 -> 7 | BJ10: =J10+AA10+AS10 -> 0 | BK10: =K10+AB10+AT10 -> 12 | ... BO10: =O10+AF10+AX10 -> 0 | BP10: =A10 -> 46059 | BQ10: =BU9 -> 468167 | BR10: =AY10+AG10+P10 -> 164906 | BS10: =BR10+BQ10 -> 633073 | BT10: 0 | BU10: =BS10-BT10 -> 633073 | BW10: =Q10+AH10+AZ10 -> 76779 | BX10: =R10+AI10+BA10 -> 148057 | BY10: =+BU10-BX10 -> 485016 | CA10: 20 | CC10: =+CB10*CA10 -> 0
A11: =1+A10 -> 46060 | B11: 1 | C11: 15 | D11: 4 | E11: 2 | F11: 11 | K11: 5 | L11: 15 | M11: 10 | P11: =C11*$B$4+D11*$D$4+E11*$E$4+F11*$F$4+G11*$G$4+H11*$H$4+I11*$I$4+J11*$J$4+K11*$K$4+L11*$L$4+M11*$M$4+N11*$N$4+O11*$O$4 -> 55833 | Q11: 203890 | R11: =+R10+P11-Q11 -> 0 | U11: 1 | V11: 1 | W11: 6 | Y11: 2 | Z11: 6 | AB11: 5 | AC11: 5 | AD11: 5 | AE11: 20 | AG11: =T11*$B$4+U11*$D$4+V11*$E$4+W11*$F$4+X11*$G$4+Y11*$H$4+Z11*$I$4+AA11*$J$4+AB11*$K$4+AC11*$L$4+AD11*$M$4+AE11*$N$4+AF11*$O$4 -> 25912 | AI11: =+AI10+AG11-AH11 -> 25912 | AJ11: 1 | AK11: 7 | AM11: 1 | AN11: 1 | AO11: 2 | AR11: 5 | AT11: 5 | AU11: 6 | AW11: 20 | AY11: =AK11*$AJ$4+AM11*$AM$4+AN11*$AN$4+AO11*$AO$4+AP11*$AP$4+AQ11*$AQ$4+AR11*$AR$4+AS11*$AS$4+AT11*$AT$4+AU11*$AU$4+AV11*$AV$4+AW11*$AW$4+AX11*$AX$4+$AL$4*AL11 -> 25096 | BA11: =+BA10+AY11-AZ11 -> 25096 | BB11: =B11+S11+AJ11 -> 2 | BC11: =C11+T11+AK11 -> 22 | BD11: =D11+U11+AM11 -> 6 | BE11: =E11+V11+AN11 -> 4 | BF11: =F11+W11+AO11 -> 19 | BG11: =G11+X11+AP11 -> 0 | BH11: =H11+Y11+AQ11 -> 2 | BI11: =I11+Z11+AR11 -> 11 | BJ11: =J11+AA11+AS11 -> 0 | BK11: =K11+AB11+AT11 -> 15 | ... BO11: =O11+AF11+AX11 -> 0 | BP11: =A11 -> 46060 | BQ11: =BU10 -> 633073 | BR11: =AY11+AG11+P11 -> 106841 | BS11: =BR11+BQ11 -> 739914 | BT11: 0 | BU11: =BS11-BT11 -> 739914 | BW11: =Q11+AH11+AZ11 -> 203890 | BX11: =R11+AI11+BA11 -> 51008 | BY11: =+BU11-BX11 -> 688906 | CA11: 10 | CC11: =+CB11*CA11 -> 0
A12: =1+A11 -> 46061 | D12: 1 | E12: 2 | F12: =8+6 -> 14 | I12: 5 | K12: 5 | L12: 10 | M12: 30 | N12: 20 | P12: =C12*$B$4+D12*$D$4+E12*$E$4+F12*$F$4+G12*$G$4+H12*$H$4+I12*$I$4+J12*$J$4+K12*$K$4+L12*$L$4+M12*$M$4+N12*$N$4+O12*$O$4 -> 47283 | R12: =+R11+P12-Q12 -> 47283 | S12: 1 | T12: 3 | U12: 2 | V12: 1 | W12: 9 | Y12: 3 | AB12: 4 | AC12: 5 | AD12: 10 | AG12: =T12*$B$4+U12*$D$4+V12*$E$4+W12*$F$4+X12*$G$4+Y12*$H$4+Z12*$I$4+AA12*$J$4+AB12*$K$4+AC12*$L$4+AD12*$M$4+AE12*$N$4+AF12*$O$4 -> 30243 | AH12: 56155 | AI12: =+AI11+AG12-AH12 -> 0 | AL12: 1 | AM12: 5 | AN12: 2 | AO12: =6+7 -> 13 | AQ12: 7 | AR12: 5 | AT12: 11 | AU12: 8 | AV12: 5 | AY12: =AK12*$AJ$4+AM12*$AM$4+AN12*$AN$4+AO12*$AO$4+AP12*$AP$4+AQ12*$AQ$4+AR12*$AR$4+AS12*$AS$4+AT12*$AT$4+AU12*$AU$4+AV12*$AV$4+AW12*$AW$4+AX12*$AX$4+$AL$4*AL12 -> 47624 | AZ12: 72720 | BA12: =+BA11+AY12-AZ12 -> 0 | BB12: =B12+S12+AJ12 -> 1 | BC12: =C12+T12+AK12 -> 3 | BD12: =D12+U12+AM12 -> 8 | BE12: =E12+V12+AN12 -> 5 | BF12: =F12+W12+AO12 -> 36 | BG12: =G12+X12+AP12 -> 0 | BH12: =H12+Y12+AQ12 -> 10 | BI12: =I12+Z12+AR12 -> 10 | BJ12: =J12+AA12+AS12 -> 0 | BK12: =K12+AB12+AT12 -> 20 | ... BO12: =O12+AF12+AX12 -> 0 | BP12: =A12 -> 46061 | BQ12: =BU11 -> 739914 | BR12: =AY12+AG12+P12 -> 125150 | BS12: =BR12+BQ12 -> 865064 | BT12: 509146 | BU12: =BS12-BT12 -> 355918 | BW12: =Q12+AH12+AZ12 -> 128875 | BX12: =R12+AI12+BA12 -> 47283 | BY12: =+BU12-BX12 -> 308635 | CA12: TOTAL | CC12: =SUM(CC5:CC11) -> 0
A13: =1+A12 -> 46062 | D13: 5 | E13: 2 | F13: 19 | H13: 10 | I13: 3 | K13: 5 | L13: 10 | M13: 20 | N13: 20 | P13: =C13*$B$4+D13*$D$4+E13*$E$4+F13*$F$4+G13*$G$4+H13*$H$4+I13*$I$4+J13*$J$4+K13*$K$4+L13*$L$4+M13*$M$4+N13*$N$4+O13*$O$4 -> 63884 | R13: =+R12+P13-Q13 -> 111167 | U13: 1 | V13: 1 | W13: 4 | Z13: 5 | AB13: 5 | AC13: 5 | AD13: 5 | AG13: =T13*$B$4+U13*$D$4+V13*$E$4+W13*$F$4+X13*$G$4+Y13*$H$4+Z13*$I$4+AA13*$J$4+AB13*$K$4+AC13*$L$4+AD13*$M$4+AE13*$N$4+AF13*$O$4 -> 15844 | AH13: 15844 | AI13: =+AI12+AG13-AH13 -> 0 | AJ13: 1 | AK13: 4 | AM13: 2 | AN13: 2 | AO13: 7 | AQ13: 4 | AV13: 5 | AY13: =AK13*$AJ$4+AM13*$AM$4+AN13*$AN$4+AO13*$AO$4+AP13*$AP$4+AQ13*$AQ$4+AR13*$AR$4+AS13*$AS$4+AT13*$AT$4+AU13*$AU$4+AV13*$AV$4+AW13*$AW$4+AX13*$AX$4+$AL$4*AL13 -> 25789 | AZ13: 25789 | BA13: =+BA12+AY13-AZ13 -> 0 | BB13: =B13+S13+AJ13 -> 1 | BC13: =C13+T13+AK13 -> 4 | BD13: =D13+U13+AM13 -> 8 | BE13: =E13+V13+AN13 -> 5 | BF13: =F13+W13+AO13 -> 30 | BG13: =G13+X13+AP13 -> 0 | BH13: =H13+Y13+AQ13 -> 14 | BI13: =I13+Z13+AR13 -> 8 | BJ13: =J13+AA13+AS13 -> 0 | BK13: =K13+AB13+AT13 -> 10 | ... BO13: =O13+AF13+AX13 -> 0 | BP13: =A13 -> 46062 | BQ13: =BU12 -> 355918 | BR13: =AY13+AG13+P13 -> 105517 | BS13: =BR13+BQ13 -> 461435 | BT13: 0 | BU13: =BS13-BT13 -> 461435 | BW13: =Q13+AH13+AZ13 -> 41633 | BX13: =R13+AI13+BA13 -> 111167 | BY13: =+BU13-BX13 -> 350268 | CA13: HOLD
