Workbook

Sheet README
A1: FORKS N KNIVES — GULBERG — CONNECTED FINANCIAL WORKBOOK
A4: THIS WORKBOOK IS PRE-FILLED WITH SEPTEMBER 2026 ACTUALS
A6: Every real September transaction from the audited 2026-SEPTEMBER-C-5 workbook (603 expense/director/payroll
A7: lines, tying exactly to the audited Total Expense of 13,968,109) and the real September staff roster (76
A8: employees) is already loaded — see Sales, Expense Entry, Directors and Payroll. The P&L Summary and Dashboard are
A9: showing September's actual financial position right now. Keep adding new dated rows for October onward and
A10: everything recalculates live.
A12: ITEM CODES — THE BACKBONE THAT LINKS EVERYTHING
A14: Every one of the 481 real inventory items now has a permanent, professional Item Code — a 2-letter category
A15: prefix plus a 3-digit number, e.g. FD-001 (Food & Beverage), PK-014 (Packaging & Paper). The 10 categories are:
A16: FD Food & Beverage, PK Packaging & Paper, CL Cleaning & Sanitation, PT Party & Decor, ST Stationery & Office
A17: Supplies, MK Marketing & POS Materials, UN Uniform & Apparel, EQ Equipment & Smallwares, DV Vehicle & Delivery
... A133: — nothing there should ever be typed over.

Sheet Dashboard
A1: DASHBOARD — FORKS N KNIVES, GULBERG
A2: Live KPIs pulled from every tab. Nothing to enter here.
A4: Total Sales (Sales tab) | B4: =Sales!$G$3010 -> 14012331
A5: Total Cost of Goods Used (P&L) | B5: ='P&L Summary'!$B$18 -> 0
A6: Total Direct Operating Expenses (P&L) | B6: ='P&L Summary'!$B$43 -> 13510202
A7: Operating Profit | B7: ='P&L Summary'!$B$47 -> 502129
A8: Total Director Draws | B8: =Directors!$B$11 -> 457907
A9: Net Profit After Director Draws | B9: ='P&L Summary'!$B$47-Directors!$B$11 -> 44222
A10: Current Closing Cash (last entered day) | B10: =IFERROR(INDEX('Cash Book'!$F$5:$F$35,MATCH(2,1/('Cash Book'!$A$5:$A$35<>""),1)),0) -> 502129
A11: Total Inventory Value on Hand | B11: =Inventory!$L$487 -> 4433397.6
A12: Total Payables Outstanding | B12: =SUM(Payables!$F$5:$F$3000) -> 0
A13: Open / Unreceived Purchase Orders | B13: =COUNTIFS('Purchase Orders'!$L$5:$L$3000,"Ordered") -> 0

Sheet P&L Summary
A1: P&L SUMMARY — the one tab that rolls up every other tab
A2: Pulls live from Sales, Expense Entry, Issue Log, Directors and Payroll. Food/Packaging/Cleaning/Party & Decor/Stationery/Uniform/Equipment/Vehicle/Fuel costs are consumption-based (from Issue Log) when tracked item-by-item; everything else comes straight from Expense Entry.
A4: REVENUE
A5: Sales Collected (from Sales tab) | B5: =Sales!$G$3010 -> 14012331
A7: COST OF GOODS USED (consumption basis, from Issue Log)
A8: Cleaning & Sanitation | B8: =SUMIFS('Issue Log'!$G$5:$G$6000,'Issue Log'!$J$5:$J$6000,"Cleaning & Sanitation") -> 0
A9: Equipment & Smallwares | B9: =SUMIFS('Issue Log'!$G$5:$G$6000,'Issue Log'!$J$5:$J$6000,"Equipment & Smallwares") -> 0
A10: Food & Beverage | B10: =SUMIFS('Issue Log'!$G$5:$G$6000,'Issue Log'!$J$5:$J$6000,"Food & Beverage") -> 0
A11: Fuel & Gas | B11: =SUMIFS('Issue Log'!$G$5:$G$6000,'Issue Log'!$J$5:$J$6000,"Fuel & Gas") -> 0
A12: Marketing & POS Materials | B12: =SUMIFS('Issue Log'!$G$5:$G$6000,'Issue Log'!$J$5:$J$6000,"Marketing & POS Materials") -> 0
A13: Packaging & Paper | B13: =SUMIFS('Issue Log'!$G$5:$G$6000,'Issue Log'!$J$5:$J$6000,"Packaging & Paper") -> 0
A14: Party & Decor | B14: =SUMIFS('Issue Log'!$G$5:$G$6000,'Issue Log'!$J$5:$J$6000,"Party & Decor") -> 0
A15: Stationery & Office Supplies | B15: =SUMIFS('Issue Log'!$G$5:$G$6000,'Issue Log'!$J$5:$J$6000,"Stationery & Office Supplies") -> 0
A16: Uniform & Apparel | B16: =SUMIFS('Issue Log'!$G$5:$G$6000,'Issue Log'!$J$5:$J$6000,"Uniform & Apparel") -> 0
A17: Vehicle & Delivery Equipment | B17: =SUMIFS('Issue Log'!$G$5:$G$6000,'Issue Log'!$J$5:$J$6000,"Vehicle & Delivery Equipment") -> 0
A18: SUBTOTAL — COST OF GOODS USED | B18: ='P&L Summary'!$B$8+'P&L Summary'!$B$9+'P&L Summary'!$B$10+'P&L Summary'!$B$11+'P&L Summary'!$B$12+'P&L Summary'!$B$13+'P&L Summary'!$B$14+'P&L Summary'!$B$15+'P&L Summary'!$B$16+'P&L Summary'!$B$17 -> 0
A20: DIRECT OPERATING EXPENSES (from Expense Entry, cash categories)
A21: Food | B21: =SUMIFS('Expense Entry'!$K$5:$K$6000,'Expense Entry'!$E$5:$E$6000,"Food") -> 6717236
A22: Packaging | B22: =SUMIFS('Expense Entry'!$K$5:$K$6000,'Expense Entry'!$E$5:$E$6000,"Packaging") -> 418045
A23: Cleaning & Sanitation | B23: =SUMIFS('Expense Entry'!$K$5:$K$6000,'Expense Entry'!$E$5:$E$6000,"Cleaning & Sanitation") -> 160230
A24: Party & Decor | B24: =SUMIFS('Expense Entry'!$K$5:$K$6000,'Expense Entry'!$E$5:$E$6000,"Party & Decor") -> 10140
A25: Stationery & Office Supplies | B25: =SUMIFS('Expense Entry'!$K$5:$K$6000,'Expense Entry'!$E$5:$E$6000,"Stationery & Office Supplies") -> 17600
A26: Marketing | B26: =SUMIFS('Expense Entry'!$K$5:$K$6000,'Expense Entry'!$E$5:$E$6000,"Marketing") -> 9250
A27: Uniform & Apparel | B27: =SUMIFS('Expense Entry'!$K$5:$K$6000,'Expense Entry'!$E$5:$E$6000,"Uniform & Apparel") -> 140560
A28: Equipment & Smallwares | B28: =SUMIFS('Expense Entry'!$K$5:$K$6000,'Expense Entry'!$E$5:$E$6000,"Equipment & Smallwares") -> 29290
A29: Vehicle & Delivery Maintenance | B29: =SUMIFS('Expense Entry'!$K$5:$K$6000,'Expense Entry'!$E$5:$E$6000,"Vehicle & Delivery Maintenance") -> 0
A30: Fuel & Gas | B30: =SUMIFS('Expense Entry'!$K$5:$K$6000,'Expense Entry'!$E$5:$E$6000,"Fuel & Gas") -> 0
A31: Payroll | B31: =SUMIFS('Expense Entry'!$K$5:$K$6000,'Expense Entry'!$E$5:$E$6000,"Payroll") -> 2439333 | D31: Actual cash payroll paid out (per Expense Entry). The Payroll tab's base-salary roster is a separate HR reference, not re-added here.
A32: Utilities (Electricity/Water) | B32: =SUMIFS('Expense Entry'!$K$5:$K$6000,'Expense Entry'!$E$5:$E$6000,"Utilities (Electricity/Water)") -> 2048915
A33: Distribution Cost | B33: =SUMIFS('Expense Entry'!$K$5:$K$6000,'Expense Entry'!$E$5:$E$6000,"Distribution Cost") -> 11680
A34: Delivery Charges | B34: =SUMIFS('Expense Entry'!$K$5:$K$6000,'Expense Entry'!$E$5:$E$6000,"Delivery Charges") -> 1850
A35: Interstore Transfers | B35: =SUMIFS('Expense Entry'!$K$5:$K$6000,'Expense Entry'!$E$5:$E$6000,"Interstore Transfers") -> 436000
A36: Employee Meals & Medical | B36: =SUMIFS('Expense Entry'!$K$5:$K$6000,'Expense Entry'!$E$5:$E$6000,"Employee Meals & Medical") -> 24143
A37: Charge to Restaurant | B37: =SUMIFS('Expense Entry'!$K$5:$K$6000,'Expense Entry'!$E$5:$E$6000,"Charge to Restaurant") -> 45394
A38: Repairs & Maintenance | B38: =SUMIFS('Expense Entry'!$K$5:$K$6000,'Expense Entry'!$E$5:$E$6000,"Repairs & Maintenance") -> 209690
A39: Government Charges & Taxes | B39: =SUMIFS('Expense Entry'!$K$5:$K$6000,'Expense Entry'!$E$5:$E$6000,"Government Charges & Taxes") -> 602937
A40: Food Panda Commission | B40: =SUMIFS('Expense Entry'!$K$5:$K$6000,'Expense Entry'!$E$5:$E$6000,"Food Panda Commission") -> 178649
A41: Miscellaneous | B41: =SUMIFS('Expense Entry'!$K$5:$K$6000,'Expense Entry'!$E$5:$E$6000,"Miscellaneous") -> 9260
A42: Donation | B42: =SUMIFS('Expense Entry'!$K$5:$K$6000,'Expense Entry'!$E$5:$E$6000,"Donation") -> 0
A43: SUBTOTAL — DIRECT OPERATING EXPENSES | B43: ='P&L Summary'!$B$21+'P&L Summary'!$B$22+'P&L Summary'!$B$23+'P&L Summary'!$B$24+'P&L Summary'!$B$25+'P&L Summary'!$B$26+'P&L Summary'!$B$27+'P&L Summary'!$B$28+'P&L Summary'!$B$29+'P&L Summary'!$B$30+'P&L Summary'!$B$31+'P&L Summary'!$B$32+'P&L Summary'!$B$33+'P&L Summary'!$B$34+'P&L Summary'!$B$35+'P&L Summary'!$B$36+'P&L Summary'!$B$37+'P&L Summary'!$B$38+'P&L Summary'!$B$39+'P&L Summary'!$B$40+'P&L Summary'!$B$41+'P&L Summary'!$B$42 -> 13510202
...

Sheet Sales
A1: SALES — daily sales by channel
A2: One row per day. Total Sale is automatic and feeds the Cash Book / P&L / Dashboard. Add new dated rows as months go by.
A4: Date | B4: Dine-in | C4: Takeaway | D4: Delivery | E4: Food Panda | F4: Third Party | G4: Total Sale | H4: Notes
A5: 46266 | B5: 240340 | C5: 30409 | D5: 158049 | E5: 8036 | F5: 0 | G5: =IF($A5="","",SUM($B5:$F5)) -> 436834
A6: 46267 | B6: 205739 | C6: 14835 | D6: 204614 | E6: 10100 | F6: 0 | G6: =IF($A6="","",SUM($B6:$F6)) -> 435288
A7: 46268 | B7: 234024 | C7: 23937 | D7: 220615 | E7: 3500 | F7: 0 | G7: =IF($A7="","",SUM($B7:$F7)) -> 482076
A8: 46269 | B8: 310832 | C8: 29420 | D8: 183524 | E8: 3589 | F8: 0 | G8: =IF($A8="","",SUM($B8:$F8)) -> 527365
A9: 46270 | B9: 243677 | C9: 32128 | D9: 211739 | E9: 12056 | F9: 0 | G9: =IF($A9="","",SUM($B9:$F9)) -> 499600
A10: 46271 | B10: 254640 | C10: 29168 | D10: 218888 | E10: 8898 | F10: 0 | G10: =IF($A10="","",SUM($B10:$F10)) -> 511594
A11: 46272 | B11: 258529 | C11: 39810 | D11: 135797 | E11: 9768 | F11: 22087 | G11: =IF($A11="","",SUM($B11:$F11)) -> 465991
A12: 46273 | B12: 245296 | C12: 30606 | D12: 146125 | E12: 1829 | F12: 8318 | G12: =IF($A12="","",SUM($B12:$F12)) -> 432174
A13: 46274 | B13: 216540 | C13: 38433 | D13: 142018 | E13: 7358 | F13: 32990 | G13: =IF($A13="","",SUM($B13:$F13)) -> 437339
A14: 46275 | B14: 257101 | C14: 27110 | D14: 124540 | E14: 10017 | F14: 11118 | G14: =IF($A14="","",SUM($B14:$F14)) -> 429886
A15: 46276 | B15: 372389 | C15: 26793 | D15: 171079 | E15: 4167 | F15: 36299 | G15: =IF($A15="","",SUM($B15:$F15)) -> 610727
A16: 46277 | B16: 246019 | C16: 30190 | D16: 200757 | E16: 9705 | F16: 29264 | G16: =IF($A16="","",SUM($B16:$F16)) -> 515935
... A32: 46293 | B32: 168424 | C32: 30763 | D32: 130000 | E32: 8883 | F32: 12956 | G32: =IF($A32="","",SUM($B32:$F32)) -> 351026
A33: 46294 | B33: 402974 | C33: 0 | D33: 0 | E33: 0 | F33: 0 | G33: =IF($A33="","",SUM($B33:$F33)) -> 402974 | H33: Channel breakdown unavailable for this day — lump total per Sep detail report (booked under Dine-in)
A34: 46295 | B34: 424788 | C34: 0 | D34: 0 | E34: 0 | F34: 0 | G34: =IF($A34="","",SUM($B34:$F34)) -> 424788 | H34: Channel breakdown unavailable for this day — lump total per Sep detail report (booked under Dine-in)
G35: =IF($A35="","",SUM($B35:$F35))
G36: =IF($A36="","",SUM($B36:$F36))
G37: =IF($A37="","",SUM($B37:$F37))
G38: =IF($A38="","",SUM($B38:$F38))
G39: =IF($A39="","",SUM($B39:$F39))
G40: =IF($A40="","",SUM($B40:$F40))
G41: =IF($A41="","",SUM($B41:$F41))
G42: =IF($A42="","",SUM($B42:$F42))
G43: =IF($A43="","",SUM($B43:$F43))
G44: =IF($A44="","",SUM($B44:$F44))
G45: =IF($A45="","",SUM($B45:$F45))
G46: =IF($A46="","",SUM($B46:$F46))
... G404: =IF($A404="","",SUM($B404:$F404))
F3010: TOTAL: | G3010: =SUM($G$5:$G$3000) -> 14012331

Sheet Food Panda
A1: FOOD PANDA — settlement reconciliation (catches under-payment)
A2: Food Panda's deductions (Commission/Fee & Adjustments/Tax) are NOT a cash expense Zeeshan pays -- they are subtracted before the net amount ever reaches the bank. This tab checks two things: (1) does Food Panda's own statement add up (Gross - Commission - Fee&Adj - Tax + Refund = their stated Net Earning)? and (2) does the actual bank deposit match? Gross Sale/Total Earning is the only number you need going in -- everything else is either calculated from the pattern below or typed in once their statement arrives.
A4: PATTERN RATES (derived from real Sep-2026 statements -- edit if Food Panda changes terms)
A5: Brand | B5: Commission % | C5: Tax % | D5: Typical Fee & Adj. (PKR, flat)
A6: Frostings | B6: 0.26 | C6: 0.062 | D6: 800
A7: Pizza Kitchen | B7: 0.22 | C7: 0.037 | D7: 400
A8: Combined / Other | B8: 0.23 | C8: 0.05 | D8: 500
A10: ⚠ Found during the Sep-30 sample: Pizza Kitchen-Gulberg's own statement didn't add up internally (Total 27,429 − Commission 5,771 − Fee 400 − Tax 7,159 = 14,099, but their sheet showed Net Earning 20,271 -- a 6,172 PKR gap). Every other branch that day reconciled exactly. Worth confirming the real figure against Food Panda's own portal/PDF (a transcription slip is possible) -- and if it recurs, raise it with them directly.
A12: Period / Settlement Date | B12: Brand | C12: Gross Sale (Total Earning) | D12: Expected Net (pattern estimate) | E12: FP Reported Commission | F12: FP Reported Fee & Adj. | G12: FP Reported Tax | H12: FP Reported Refund (+) | I12: FP Reported Net Earning | J12: Recomputed Net (Gross-Comm-Fee-Tax+Refund) | K12: Statement Check | L12: Actual Bank Deposit Received | M12: Deposit vs Recomputed Variance | N12: Status | O12: Notes
A13: 30-Sep-2026 | B13: Frostings | C13: 1782 | D13: =IF($C13="","",IF($B13="","",$C13*(1-VLOOKUP($B13,$A$6:$D$8,2,0)-VLOOKUP($B13,$A$6:$D$8,3,0))-VLOOKUP($B13,$A$6:$D$8,4,0))) -> 408.196 | E13: 454 | F13: 800 | G13: 137 | H13: 0 | I13: 390 | J13: =IF($C13="","",$C13-$E13-$F13-$G13+$H13) -> 391 | K13: =IF(OR($I13="",$J13=""),"",IF(ABS($I13-$J13)<=2,"OK","⚠ FP statement doesn't add up -- verify")) -> OK | M13: =IF($L13="","",$L13-IF($J13="",$D13,$J13)) | N13: =IF($L13="","",IF($M13<-200,"⚠ SHORT -- follow up with Food Panda",IF($M13>200,"Over (unexpected)","OK"))) | O13: Worked example from the actual portal statement -- enter the real bank deposit in col L once received.
A14: 30-Sep-2026 | B14: Pizza Kitchen | C14: 27429 | D14: =IF($C14="","",IF($B14="","",$C14*(1-VLOOKUP($B14,$A$6:$D$8,2,0)-VLOOKUP($B14,$A$6:$D$8,3,0))-VLOOKUP($B14,$A$6:$D$8,4,0))) -> 19979.747 | E14: 5771 | F14: 400 | G14: 7159 | H14: 0 | I14: 20271 | J14: =IF($C14="","",$C14-$E14-$F14-$G14+$H14) -> 14099 | K14: =IF(OR($I14="",$J14=""),"",IF(ABS($I14-$J14)<=2,"OK","⚠ FP statement doesn't add up -- verify")) -> ⚠ FP statement doesn't add up -- verify | M14: =IF($L14="","",$L14-IF($J14="",$D14,$J14)) | N14: =IF($L14="","",IF($M14<-200,"⚠ SHORT -- follow up with Food Panda",IF($M14>200,"Over (unexpected)","OK"))) | O14: Worked example -- this is the row that flags the statement mismatch described above.
D15: =IF($C15="","",IF($B15="","",$C15*(1-VLOOKUP($B15,$A$6:$D$8,2,0)-VLOOKUP($B15,$A$6:$D$8,3,0))-VLOOKUP($B15,$A$6:$D$8,4,0))) | J15: =IF($C15="","",$C15-$E15-$F15-$G15+$H15) | K15: =IF(OR($I15="",$J15=""),"",IF(ABS($I15-$J15)<=2,"OK","⚠ FP statement doesn't add up -- verify")) | M15: =IF($L15="","",$L15-IF($J15="",$D15,$J15)) | N15: =IF($L15="","",IF($M15<-200,"⚠ SHORT -- follow up with Food Panda",IF($M15>200,"Over (unexpected)","OK")))
D16: =IF($C16="","",IF($B16="","",$C16*(1-VLOOKUP($B16,$A$6:$D$8,2,0)-VLOOKUP($B16,$A$6:$D$8,3,0))-VLOOKUP($B16,$A$6:$D$8,4,0))) | J16: =IF($C16="","",$C16-$E16-$F16-$G16+$H16) | K16: =IF(OR($I16="",$J16=""),"",IF(ABS($I16-$J16)<=2,"OK","⚠ FP statement doesn't add up -- verify")) | M16: =IF($L16="","",$L16-IF($J16="",$D16,$J16)) | N16: =IF($L16="","",IF($M16<-200,"⚠ SHORT -- follow up with Food Panda",IF($M16>200,"Over (unexpected)","OK")))
D17: =IF($C17="","",IF($B17="","",$C17*(1-VLOOKUP($B17,$A$6:$D$8,2,0)-VLOOKUP($B17,$A$6:$D$8,3,0))-VLOOKUP($B17,$A$6:$D$8,4,0))) | J17: =IF($C17="","",$C17-$E17-$F17-$G17+$H17) | K17: =IF(OR($I17="",$J17=""),"",IF(ABS($I17-$J17)<=2,"OK","⚠ FP statement doesn't add up -- verify")) | M17: =IF($L17="","",$L17-IF($J17="",$D17,$J17)) | N17: =IF($L17="","",IF($M17<-200,"⚠ SHORT -- follow up with Food Panda",IF($M17>200,"Over (unexpected)","OK")))
D18: =IF($C18="","",IF($B18="","",$C18*(1-VLOOKUP($B18,$A$6:$D$8,2,0)-VLOOKUP($B18,$A$6:$D$8,3,0))-VLOOKUP($B18,$A$6:$D$8,4,0))) | J18: =IF($C18="","",$C18-$E18-$F18-$G18+$H18) | K18: =IF(OR($I18="",$J18=""),"",IF(ABS($I18-$J18)<=2,"OK","⚠ FP statement doesn't add up -- verify")) | M18: =IF($L18="","",$L18-IF($J18="",$D18,$J18)) | N18: =IF($L18="","",IF($M18<-200,"⚠ SHORT -- follow up with Food Panda",IF($M18>200,"Over (unexpected)","OK")))
D19: =IF($C19="","",IF($B19="","",$C19*(1-VLOOKUP($B19,$A$6:$D$8,2,0)-VLOOKUP($B19,$A$6:$D$8,3,0))-VLOOKUP($B19,$A$6:$D$8,4,0))) | J19: =IF($C19="","",$C19-$E19-$F19-$G19+$H19) | K19: =IF(OR($I19="",$J19=""),"",IF(ABS($I19-$J19)<=2,"OK","⚠ FP statement doesn't add up -- verify")) | M19: =IF($L19="","",$L19-IF($J19="",$D19,$J19)) | N19: =IF($L19="","",IF($M19<-200,"⚠ SHORT -- follow up with Food Panda",IF($M19>200,"Over (unexpected)","OK")))
D20: =IF($C20="","",IF($B20="","",$C20*(1-VLOOKUP($B20,$A$6:$D$8,2,0)-VLOOKUP($B20,$A$6:$D$8,3,0))-VLOOKUP($B20,$A$6:$D$8,4,0))) | J20: =IF($C20="","",$C20-$E20-$F20-$G20+$H20) | K20: =IF(OR($I20="",$J20=""),"",IF(ABS($I20-$J20)<=2,"OK","⚠ FP statement doesn't add up -- verify")) | M20: =IF($L20="","",$L20-IF($J20="",$D20,$J20)) | N20: =IF($L20="","",IF($M20<-200,"⚠ SHORT -- follow up with Food Panda",IF($M20>200,"Over (unexpected)","OK")))
D21: =IF($C21="","",IF($B21="","",$C21*(1-VLOOKUP($B21,$A$6:$D$8,2,0)-VLOOKUP($B21,$A$6:$D$8,3,0))-VLOOKUP($B21,$A$6:$D$8,4,0))) | J21: =IF($C21="","",$C21-$E21-$F21-$G21+$H21) | K21: =IF(OR($I21="",$J21=""),"",IF(ABS($I21-$J21)<=2,"OK","⚠ FP statement doesn't add up -- verify")) | M21: =IF($L21="","",$L21-IF($J21="",$D21,$J21)) | N21: =IF($L21="","",IF($M21<-200,"⚠ SHORT -- follow up with Food Panda",IF($M21>200,"Over (unexpected)","OK")))
D22: =IF($C22="","",IF($B22="","",$C22*(1-VLOOKUP($B22,$A$6:$D$8,2,0)-VLOOKUP($B22,$A$6:$D$8,3,0))-VLOOKUP($B22,$A$6:$D$8,4,0))) | J22: =IF($C22="","",$C22-$E22-$F22-$G22+$H22) | K22: =IF(OR($I22="",$J22=""),"",IF(ABS($I22-$J22)<=2,"OK","⚠ FP statement doesn't add up -- verify")) | M22: =IF($L22="","",$L22-IF($J22="",$D22,$J22)) | N22: =IF($L22="","",IF($M22<-200,"⚠ SHORT -- follow up with Food Panda",IF($M22>200,"Over (unexpected)","OK")))
D23: =IF($C23="","",IF($B23="","",$C23*(1-VLOOKUP($B23,$A$6:$D$8,2,0)-VLOOKUP($B23,$A$6:$D$8,3,0))-VLOOKUP($B23,$A$6:$D$8,4,0))) | J23: =IF($C23="","",$C23-$E23-$F23-$G23+$H23) | K23: =IF(OR($I23="",$J23=""),"",IF(ABS($I23-$J23)<=2,"OK","⚠ FP statement doesn't add up -- verify")) | M23: =IF($L23="","",$L23-IF($J23="",$D23,$J23)) | N23: =IF($L23="","",IF($M23<-200,"⚠ SHORT -- follow up with Food Panda",IF($M23>200,"Over (unexpected)","OK")))
D24: =IF($C24="","",IF($B24="","",$C24*(1-VLOOKUP($B24,$A$6:$D$8,2,0)-VLOOKUP($B24,$A$6:$D$8,3,0))-VLOOKUP($B24,$A$6:$D$8,4,0))) | J24: =IF($C24="","",$C24-$E24-$F24-$G24+$H24) | K24: =IF(OR($I24="",$J24=""),"",IF(ABS($I24-$J24)<=2,"OK","⚠ FP statement doesn't add up -- verify")) | M24: =IF($L24="","",$L24-IF($J24="",$D24,$J24)) | N24: =IF($L24="","",IF($M24<-200,"⚠ SHORT -- follow up with Food Panda",IF($M24>200,"Over (unexpected)","OK")))
D25: =IF($C25="","",IF($B25="","",$C25*(1-VLOOKUP($B25,$A$6:$D$8,2,0)-VLOOKUP($B25,$A$6:$D$8,3,0))-VLOOKUP($B25,$A$6:$D$8,4,0))) | J25: =IF($C25="","",$C25-$E25-$F25-$G25+$H25) | K25: =IF(OR($I25="",$J25=""),"",IF(ABS($I25-$J25)<=2,"OK","⚠ FP statement doesn't add up -- verify")) | M25: =IF($L25="","",$L25-IF($J25="",$D25,$J25)) | N25: =IF($L25="","",IF($M25<-200,"⚠ SHORT -- follow up with Food Panda",IF($M25>200,"Over (unexpected)","OK")))
D26: =IF($C26="","",IF($B26="","",$C26*(1-VLOOKUP($B26,$A$6:$D$8,2,0)-VLOOKUP($B26,$A$6:$D$8,3,0))-VLOOKUP($B26,$A$6:$D$8,4,0))) | J26: =IF($C26="","",$C26-$E26-$F26-$G26+$H26) | K26: =IF(OR($I26="",$J26=""),"",IF(ABS($I26-$J26)<=2,"OK","⚠ FP statement doesn't add up -- verify")) | M26: =IF($L26="","",$L26-IF($J26="",$D26,$J26)) | N26: =IF($L26="","",IF($M26<-200,"⚠ SHORT -- follow up with Food Panda",IF($M26>200,"Over (unexpected)","OK")))
... D72: =IF($C72="","",IF($B72="","",$C72*(1-VLOOKUP($B72,$A$6:$D$8,2,0)-VLOOKUP($B72,$A$6:$D$8,3,0))-VLOOKUP($B72,$A$6:$D$8,4,0))) | J72: =IF($C72="","",$C72-$E72-$F72-$G72+$H72) | K72: =IF(OR($I72="",$J72=""),"",IF(ABS($I72-$J72)<=2,"OK","⚠ FP statement doesn't add up -- verify")) | M72: =IF($L72="","",$L72-IF($J72="",$D72,$J72)) | N72: =IF($L72="","",IF($M72<-200,"⚠ SHORT -- follow up with Food Panda",IF($M72>200,"Over (unexpected)","OK")))

Sheet Expense Entry
A1: EXPENSE ENTRY — single input tab (Zeeshan)
A2: Pick a Category. For 'Inventory Purchase', pick the standard Item Code (name/unit/rate fill in automatically) -> flows into the Inventory tab by code. 'Director Draw'/'Payroll/Employee Charge'=non-cash, goes to Directors/Payroll tabs. 'Payable Payment'=cash paid against a received Purchase Order (enter Linked PO#). Everything else = direct cash expense.
A4: Date | B4: # | C4: Vendor / Payee | D4: Description | E4: Category | F4: Item Code | G4: Item Name (auto) | H4: Qty | I4: Unit | J4: Rate | K4: Amount (PKR) | L4: Linked PO# (Payable Payment) | M4: Charged To (Director/Employee) | N4: Entered By | O4: Notes | P4: Cash Impact | Q4: Inventory Qty In | U4: ItemLUT (lookup table, do not edit)
A5: 46266 | B5: =IF($A5="","",ROW()-4) -> 1 | C5: - | D5: QR JAZZ CASH PAYMENT | E5: Director Draw | G5: =IFERROR(VLOOKUP($F5,ItemList_Full,2,0),"") | I5: =IFERROR(VLOOKUP($F5,ItemList_Full,3,0),"") | J5: =IFERROR(VLOOKUP($F5,ItemList_Full,4,0),"") | K5: 36390 | M5: Yasir Sb | N5: Zeeshan (Sept import) | P5: =IF($E5="","",IF(OR($E5="Director Draw",$E5="Payroll/Employee Charge"),0,-$K5)) -> 0 | Q5: =IF($E5="Inventory Purchase",$H5,0) -> 0 | U5: FD-001 | V5: CHEESE YELLOW | W5: CTN | X5: 16900 | Y5: Food & Beverage
A6: 46266 | B6: =IF($A6="","",ROW()-4) -> 2 | C6: - | D6: T.A INV# 03,17 MEAL FOR IMRAN TAHIR SB | E6: Director Draw | G6: =IFERROR(VLOOKUP($F6,ItemList_Full,2,0),"") | I6: =IFERROR(VLOOKUP($F6,ItemList_Full,3,0),"") | J6: =IFERROR(VLOOKUP($F6,ItemList_Full,4,0),"") | K6: 965 | M6: Imran Tahir | N6: Zeeshan (Sept import) | P6: =IF($E6="","",IF(OR($E6="Director Draw",$E6="Payroll/Employee Charge"),0,-$K6)) -> 0 | Q6: =IF($E6="Inventory Purchase",$H6,0) -> 0 | U6: FD-002 | V6: CHEESE GREEN | W6: CTN | X6: 16900 | Y6: Food & Beverage
A7: 46266 | B7: =IF($A7="","",ROW()-4) -> 3 | C7: FNK BAKERY | D7: FNK BAKERY BILL PAID | E7: Food | G7: =IFERROR(VLOOKUP($F7,ItemList_Full,2,0),"") | I7: =IFERROR(VLOOKUP($F7,ItemList_Full,3,0),"") | J7: =IFERROR(VLOOKUP($F7,ItemList_Full,4,0),"") | K7: 163704 | N7: Zeeshan (Sept import) | P7: =IF($E7="","",IF(OR($E7="Director Draw",$E7="Payroll/Employee Charge"),0,-$K7)) -> -163704 | Q7: =IF($E7="Inventory Purchase",$H7,0) -> 0 | U7: FD-003 | V7: MALAI BOTI | W7: KG | X7: 1400 | Y7: Food & Beverage
A8: 46266 | B8: =IF($A8="","",ROW()-4) -> 4 | C8: FNK GRILL | D8: FNK GRILL BILL PAID | E8: Food | G8: =IFERROR(VLOOKUP($F8,ItemList_Full,2,0),"") | I8: =IFERROR(VLOOKUP($F8,ItemList_Full,3,0),"") | J8: =IFERROR(VLOOKUP($F8,ItemList_Full,4,0),"") | K8: 17000 | N8: Zeeshan (Sept import) | P8: =IF($E8="","",IF(OR($E8="Director Draw",$E8="Payroll/Employee Charge"),0,-$K8)) -> -17000 | Q8: =IF($E8="Inventory Purchase",$H8,0) -> 0 | U8: FD-004 | V8: STEAK FILLET | W8: PCS | X8: 200 | Y8: Food & Beverage
A9: 46266 | B9: =IF($A9="","",ROW()-4) -> 5 | C9: FOOD PANDA | D9: FOOD PANDA SALE | E9: Food Panda Commission | G9: =IFERROR(VLOOKUP($F9,ItemList_Full,2,0),"") | I9: =IFERROR(VLOOKUP($F9,ItemList_Full,3,0),"") | J9: =IFERROR(VLOOKUP($F9,ItemList_Full,4,0),"") | K9: 13030 | N9: Zeeshan (Sept import) | P9: =IF($E9="","",IF(OR($E9="Director Draw",$E9="Payroll/Employee Charge"),0,-$K9)) -> -13030 | Q9: =IF($E9="Inventory Purchase",$H9,0) -> 0 | U9: FD-005 | V9: BEHARI CHICKEN | W9: KG | X9: 1150 | Y9: Food & Beverage
A10: 46266 | B10: =IF($A10="","",ROW()-4) -> 6 | C10: MIAN & SONS (BEVERAGES) | D10: COLA NEXT DRINK PAYMENT | E10: Food | G10: =IFERROR(VLOOKUP($F10,ItemList_Full,2,0),"") | I10: =IFERROR(VLOOKUP($F10,ItemList_Full,3,0),"") | J10: =IFERROR(VLOOKUP($F10,ItemList_Full,4,0),"") | K10: 70000 | N10: Zeeshan (Sept import) | P10: =IF($E10="","",IF(OR($E10="Director Draw",$E10="Payroll/Employee Charge"),0,-$K10)) -> -70000 | Q10: =IF($E10="Inventory Purchase",$H10,0) -> 0 | U10: FD-006 | V10: TIKKA TOPPING FISH AND CHICK | W10: KG | X10: 1150 | Y10: Food & Beverage
A11: 46266 | B11: =IF($A11="","",ROW()-4) -> 7 | C11: BAR | D11: ICE FOR BAR | E11: Food | G11: =IFERROR(VLOOKUP($F11,ItemList_Full,2,0),"") | I11: =IFERROR(VLOOKUP($F11,ItemList_Full,3,0),"") | J11: =IFERROR(VLOOKUP($F11,ItemList_Full,4,0),"") | K11: 900 | N11: Zeeshan (Sept import) | P11: =IF($E11="","",IF(OR($E11="Director Draw",$E11="Payroll/Employee Charge"),0,-$K11)) -> -900 | Q11: =IF($E11="Inventory Purchase",$H11,0) -> 0 | U11: FD-007 | V11: FAJITA TOPPING FISH AND CHICK | W11: KG | X11: 1150 | Y11: Food & Beverage
A12: 46266 | B12: =IF($A12="","",ROW()-4) -> 8 | C12: BREAD AND BEYOND | D12: BURGER BUN | E12: Food | G12: =IFERROR(VLOOKUP($F12,ItemList_Full,2,0),"") | I12: =IFERROR(VLOOKUP($F12,ItemList_Full,3,0),"") | J12: =IFERROR(VLOOKUP($F12,ItemList_Full,4,0),"") | K12: 2180 | N12: Zeeshan (Sept import) | P12: =IF($E12="","",IF(OR($E12="Director Draw",$E12="Payroll/Employee Charge"),0,-$K12)) -> -2180 | Q12: =IF($E12="Inventory Purchase",$H12,0) -> 0 | U12: FD-008 | V12: AL-TAYYAB DRUMMET | W12: KG | X12: 800 | Y12: Food & Beverage
A13: 46266 | B13: =IF($A13="","",ROW()-4) -> 9 | C13: STATIONERY ITEM | D13: BOOK BINDING SHEET AND TAPE | E13: Stationery & Office Supplies | G13: =IFERROR(VLOOKUP($F13,ItemList_Full,2,0),"") | I13: =IFERROR(VLOOKUP($F13,ItemList_Full,3,0),"") | J13: =IFERROR(VLOOKUP($F13,ItemList_Full,4,0),"") | K13: 650 | N13: Zeeshan (Sept import) | P13: =IF($E13="","",IF(OR($E13="Director Draw",$E13="Payroll/Employee Charge"),0,-$K13)) -> -650 | Q13: =IF($E13="Inventory Purchase",$H13,0) -> 0 | U13: FD-009 | V13: WINGS | W13: PKT | X13: 1260 | Y13: Food & Beverage
A14: 46266 | B14: =IF($A14="","",ROW()-4) -> 10 | C14: MATERIAL | D14: CROCKERY MATERIAL FOR KITCHEN | E14: Equipment & Smallwares | G14: =IFERROR(VLOOKUP($F14,ItemList_Full,2,0),"") | I14: =IFERROR(VLOOKUP($F14,ItemList_Full,3,0),"") | J14: =IFERROR(VLOOKUP($F14,ItemList_Full,4,0),"") | K14: 29000 | N14: Zeeshan (Sept import) | P14: =IF($E14="","",IF(OR($E14="Director Draw",$E14="Payroll/Employee Charge"),0,-$K14)) -> -29000 | Q14: =IF($E14="Inventory Purchase",$H14,0) -> 0 | U14: FD-010 | V14: DRUMMETTE | W14: PKT | X14: 1301 | Y14: Food & Beverage
A15: 46266 | B15: =IF($A15="","",ROW()-4) -> 11 | C15: MANAGEMENT | D15: AHSAN ZAIDI RGM | E15: Payroll | G15: =IFERROR(VLOOKUP($F15,ItemList_Full,2,0),"") | I15: =IFERROR(VLOOKUP($F15,ItemList_Full,3,0),"") | J15: =IFERROR(VLOOKUP($F15,ItemList_Full,4,0),"") | K15: 600 | N15: Zeeshan (Sept import) | P15: =IF($E15="","",IF(OR($E15="Director Draw",$E15="Payroll/Employee Charge"),0,-$K15)) -> -600 | Q15: =IF($E15="Inventory Purchase",$H15,0) -> 0 | U15: FD-011 | V15: SMOKED CHICKEN | W15: KG | X15: 1344 | Y15: Food & Beverage
A16: 46266 | B16: =IF($A16="","",ROW()-4) -> 12 | C16: BOH | D16: ZEESHAN K/M | E16: Payroll | G16: =IFERROR(VLOOKUP($F16,ItemList_Full,2,0),"") | I16: =IFERROR(VLOOKUP($F16,ItemList_Full,3,0),"") | J16: =IFERROR(VLOOKUP($F16,ItemList_Full,4,0),"") | K16: 200 | N16: Zeeshan (Sept import) | P16: =IF($E16="","",IF(OR($E16="Director Draw",$E16="Payroll/Employee Charge"),0,-$K16)) -> -200 | Q16: =IF($E16="Inventory Purchase",$H16,0) -> 0 | U16: FD-012 | V16: SAUSAGE | W16: KG | X16: 1088 | Y16: Food & Beverage
A17: 46266 | B17: =IF($A17="","",ROW()-4) -> 13 | C17: GENSET | D17: BETTERY FOR GENERATOR | E17: Repairs & Maintenance | G17: =IFERROR(VLOOKUP($F17,ItemList_Full,2,0),"") | I17: =IFERROR(VLOOKUP($F17,ItemList_Full,3,0),"") | J17: =IFERROR(VLOOKUP($F17,ItemList_Full,4,0),"") | K17: 25000 | N17: Zeeshan (Sept import) | P17: =IF($E17="","",IF(OR($E17="Director Draw",$E17="Payroll/Employee Charge"),0,-$K17)) -> -25000 | Q17: =IF($E17="Inventory Purchase",$H17,0) -> 0 | U17: FD-013 | V17: CHICKEN QEEMA K&NS | W17: KG | X17: 1122 | Y17: Food & Beverage
A18: 46266 | B18: =IF($A18="","",ROW()-4) -> 14 | C18: THERMAL PRINTER | D18: PRINTER INTERNET CONNECTOR CHANGE | E18: Repairs & Maintenance | G18: =IFERROR(VLOOKUP($F18,ItemList_Full,2,0),"") | I18: =IFERROR(VLOOKUP($F18,ItemList_Full,3,0),"") | J18: =IFERROR(VLOOKUP($F18,ItemList_Full,4,0),"") | K18: 1300 | N18: Zeeshan (Sept import) | P18: =IF($E18="","",IF(OR($E18="Director Draw",$E18="Payroll/Employee Charge"),0,-$K18)) -> -1300 | Q18: =IF($E18="Inventory Purchase",$H18,0) -> 0 | U18: FD-014 | V18: BIG BIRD KABAB | W18: PKT | X18: 1400.6 | Y18: Food & Beverage
... A23: 46267 | B23: =IF($A23="","",ROW()-4) -> 19 | C23: FOOD PANDA | D23: FOOD PANDA SALE | E23: Food Panda Commission | G23: =IFERROR(VLOOKUP($F23,ItemList_Full,2,0),"") | I23: =IFERROR(VLOOKUP($F23,ItemList_Full,3,0),"") | J23: =IFERROR(VLOOKUP($F23,ItemList_Full,4,0),"") | K23: 10100 | N23: Zeeshan (Sept import) | P23: =IF($E23="","",IF(OR($E23="Director Draw",$E23="Payroll/Employee Charge"),0,-$K23)) -> -10100 | Q23: =IF($E23="Inventory Purchase",$H23,0) -> 0 | U23: FD-019 | V23: 9 PIECE CUT | W23: PKT | X23: 1587 | Y23: Food & Beverage
A24: 46267 | B24: =IF($A24="","",ROW()-4) -> 20 | C24: - | D24: PARCAL PAYMENT FOR YASIR SB | E24: Director Draw | G24: =IFERROR(VLOOKUP($F24,ItemList_Full,2,0),"") | I24: =IFERROR(VLOOKUP($F24,ItemList_Full,3,0),"") | J24: =IFERROR(VLOOKUP($F24,ItemList_Full,4,0),"") | K24: 2880 | M24: Yasir Sb | N24: Zeeshan (Sept import) | P24: =IF($E24="","",IF(OR($E24="Director Draw",$E24="Payroll/Employee Charge"),0,-$K24)) -> 0 | Q24: =IF($E24="Inventory Purchase",$H24,0) -> 0 | U24: FD-020 | V24: REGULAR BONLESS THIGHS | W24: PKT | X24: 2410 | Y24: Food & Beverage
A25: 46267 | B25: =IF($A25="","",ROW()-4) -> 21 | C25: - | D25: DESI CHICKEN FOR BOSS HOME | E25: Director Draw | G25: =IFERROR(VLOOKUP($F25,ItemList_Full,2,0),"") | I25: =IFERROR(VLOOKUP($F25,ItemList_Full,3,0),"") | J25: =IFERROR(VLOOKUP($F25,ItemList_Full,4,0),"") | K25: 13000 | M25: Yasir Sb | N25: Zeeshan (Sept import) | P25: =IF($E25="","",IF(OR($E25="Director Draw",$E25="Payroll/Employee Charge"),0,-$K25)) -> 0 | Q25: =IF($E25="Inventory Purchase",$H25,0) -> 0 | U25: FD-021 | V25: COLA NEXT 2.25 ML | W25: PET | X25: 720 | Y25: Food & Beverage
A26: 46267 | B26: =IF($A26="","",ROW()-4) -> 22 | C26: - | D26: QR JAZZ CASH PAYMENT | E26: Director Draw | G26: =IFERROR(VLOOKUP($F26,ItemList_Full,2,0),"") | I26: =IFERROR(VLOOKUP($F26,ItemList_Full,3,0),"") | J26: =IFERROR(VLOOKUP($F26,ItemList_Full,4,0),"") | K26: 840 | M26: Yasir Sb | N26: Zeeshan (Sept import) | P26: =IF($E26="","",IF(OR($E26="Director Draw",$E26="Payroll/Employee Charge"),0,-$K26)) -> 0 | Q26: =IF($E26="Inventory Purchase",$H26,0) -> 0 | U26: FD-022 | V26: FIZUP 2.25 ML | W26: PET | X26: 720 | Y26: Food & Beverage
A27: 46267 | B27: =IF($A27="","",ROW()-4) -> 23 | C27: - | D27: T.A INV# 09 WATER FOR IMRAN TAHIR SB | E27: Director Draw | G27: =IFERROR(VLOOKUP($F27,ItemList_Full,2,0),"") | I27: =IFERROR(VLOOKUP($F27,ItemList_Full,3,0),"") | J27: =IFERROR(VLOOKUP($F27,ItemList_Full,4,0),"") | K27: 95 | M27: Imran Tahir | N27: Zeeshan (Sept import) | P27: =IF($E27="","",IF(OR($E27="Director Draw",$E27="Payroll/Employee Charge"),0,-$K27)) -> 0 | Q27: =IF($E27="Inventory Purchase",$H27,0) -> 0 | U27: FD-023 | V27: COLA NEXT 1500 ML | W27: PET | X27: 720 | Y27: Food & Beverage
A28: 46267 | B28: =IF($A28="","",ROW()-4) -> 24 | C28: ASIF ENTERPRISES (OMORE) | D28: ICE CREAM FOR BAR | E28: Food | G28: =IFERROR(VLOOKUP($F28,ItemList_Full,2,0),"") | I28: =IFERROR(VLOOKUP($F28,ItemList_Full,3,0),"") | J28: =IFERROR(VLOOKUP($F28,ItemList_Full,4,0),"") | K28: 11160 | N28: Zeeshan (Sept import) | P28: =IF($E28="","",IF(OR($E28="Director Draw",$E28="Payroll/Employee Charge"),0,-$K28)) -> -11160 | Q28: =IF($E28="Inventory Purchase",$H28,0) -> 0 | U28: FD-024 | V28: FIZE UP 1500 ML | W28: PET | X28: 720 | Y28: Food & Beverage
A29: 46267 | B29: =IF($A29="","",ROW()-4) -> 25 | C29: BAR | D29: ICE FOR BAR | E29: Food | G29: =IFERROR(VLOOKUP($F29,ItemList_Full,2,0),"") | I29: =IFERROR(VLOOKUP($F29,ItemList_Full,3,0),"") | J29: =IFERROR(VLOOKUP($F29,ItemList_Full,4,0),"") | K29: 1800 | N29: Zeeshan (Sept import) | P29: =IF($E29="","",IF(OR($E29="Director Draw",$E29="Payroll/Employee Charge"),0,-$K29)) -> -1800 | Q29: =IF($E29="Inventory Purchase",$H29,0) -> 0 | U29: FD-025 | V29: COLA NEXT 1000 ML | W29: PET | X29: 600 | Y29: Food & Beverage
A30: 46267 | B30: =IF($A30="","",ROW()-4) -> 26 | C30: FNK GRILL | D30: FNK GRILL BILL PAID | E30: Food | G30: =IFERROR(VLOOKUP($F30,ItemList_Full,2,0),"") | I30: =IFERROR(VLOOKUP($F30,ItemList_Full,3,0),"") | J30: =IFERROR(VLOOKUP($F30,ItemList_Full,4,0),"") | K30: 11000 | N30: Zeeshan (Sept import) | P30: =IF($E30="","",IF(OR($E30="Director Draw",$E30="Payroll/Employee Charge"),0,-$K30)) -> -11000 | Q30: =IF($E30="Inventory Purchase",$H30,0) -> 0 | U30: FD-026 | V30: FIZE UP 1000 ML | W30: PET | X30: 600 | Y30: Food & Beverage
A31: 46267 | B31: =IF($A31="","",ROW()-4) -> 27 | C31: K&N'S | D31: K&Ns BILL PAID | E31: Food | G31: =IFERROR(VLOOKUP($F31,ItemList_Full,2,0),"") | I31: =IFERROR(VLOOKUP($F31,ItemList_Full,3,0),"") | J31: =IFERROR(VLOOKUP($F31,ItemList_Full,4,0),"") | K31: 169000 | N31: Zeeshan (Sept import) | P31: =IF($E31="","",IF(OR($E31="Director Draw",$E31="Payroll/Employee Charge"),0,-$K31)) -> -169000 | Q31: =IF($E31="Inventory Purchase",$H31,0) -> 0 | U31: FD-027 | V31: COLA NEXT 500 ML | W31: PET | X31: 770 | Y31: Food & Beverage
A32: 46267 | B32: =IF($A32="","",ROW()-4) -> 28 | C32: CLEANING | D32: FUMIGATION CHARGES PAID | E32: Cleaning & Sanitation | G32: =IFERROR(VLOOKUP($F32,ItemList_Full,2,0),"") | I32: =IFERROR(VLOOKUP($F32,ItemList_Full,3,0),"") | J32: =IFERROR(VLOOKUP($F32,ItemList_Full,4,0),"") | K32: 10000 | N32: Zeeshan (Sept import) | P32: =IF($E32="","",IF(OR($E32="Director Draw",$E32="Payroll/Employee Charge"),0,-$K32)) -> -10000 | Q32: =IF($E32="Inventory Purchase",$H32,0) -> 0 | U32: FD-028 | V32: FIZE UP 500 ML | W32: PET | X32: 770 | Y32: Food & Beverage
A33: 46267 | B33: =IF($A33="","",ROW()-4) -> 29 | C33: WALK-IN | D33: WARMA AND RUBBET FOR MAKE TABLE AND WALKING DOOR | E33: Repairs & Maintenance | G33: =IFERROR(VLOOKUP($F33,ItemList_Full,2,0),"") | I33: =IFERROR(VLOOKUP($F33,ItemList_Full,3,0),"") | J33: =IFERROR(VLOOKUP($F33,ItemList_Full,4,0),"") | K33: 140 | N33: Zeeshan (Sept import) | P33: =IF($E33="","",IF(OR($E33="Director Draw",$E33="Payroll/Employee Charge"),0,-$K33)) -> -140 | Q33: =IF($E33="Inventory Purchase",$H33,0) -> 0 | U33: FD-029 | V33: COLA NEXT 300 ML | W33: PET | X33: 560 | Y33: Food & Beverage
A34: 46267 | B34: =IF($A34="","",ROW()-4) -> 30 | C34: KITCHEN WIRING | D34: DUCKET,FLEX PIPE AND DOUBLE BOARD SHEET FOR KITCHEN | E34: Repairs & Maintenance | G34: =IFERROR(VLOOKUP($F34,ItemList_Full,2,0),"") | I34: =IFERROR(VLOOKUP($F34,ItemList_Full,3,0),"") | J34: =IFERROR(VLOOKUP($F34,ItemList_Full,4,0),"") | K34: 2580 | N34: Zeeshan (Sept import) | P34: =IF($E34="","",IF(OR($E34="Director Draw",$E34="Payroll/Employee Charge"),0,-$K34)) -> -2580 | Q34: =IF($E34="Inventory Purchase",$H34,0) -> 0 | U34: FD-030 | V34: FIZE UP 300 ML | W34: PET | X34: 560 | Y34: Food & Beverage
A35: 46267 | B35: =IF($A35="","",ROW()-4) -> 31 | C35: MANAGEMENT | D35: AHSAN ZAIDI RGM | E35: Payroll | G35: =IFERROR(VLOOKUP($F35,ItemList_Full,2,0),"") | I35: =IFERROR(VLOOKUP($F35,ItemList_Full,3,0),"") | J35: =IFERROR(VLOOKUP($F35,ItemList_Full,4,0),"") | K35: 650 | N35: Zeeshan (Sept import) | P35: =IF($E35="","",IF(OR($E35="Director Draw",$E35="Payroll/Employee Charge"),0,-$K35)) -> -650 | Q35: =IF($E35="Inventory Purchase",$H35,0) -> 0 | U35: FD-031 | V35: WATER 1500 ML | W35: PET | X35: 380 | Y35: Food & Beverage
A36: 46267 | B36: =IF($A36="","",ROW()-4) -> 32 | C36: FOH | D36: NABEEL FOH SUPERVISOR | E36: Payroll | G36: =IFERROR(VLOOKUP($F36,ItemList_Full,2,0),"") | I36: =IFERROR(VLOOKUP($F36,ItemList_Full,3,0),"") | J36: =IFERROR(VLOOKUP($F36,ItemList_Full,4,0),"") | K36: 550 | N36: Zeeshan (Sept import) | P36: =IF($E36="","",IF(OR($E36="Director Draw",$E36="Payroll/Employee Charge"),0,-$K36)) -> -550 | Q36: =IF($E36="Inventory Purchase",$H36,0) -> 0 | U36: FD-032 | V36: WATER 500 ML | W36: PET | X36: 380 | Y36: Food & Beverage
A37: 46267 | B37: =IF($A37="","",ROW()-4) -> 33 | C37: FOH | D37: KHALIL CASHIER | E37: Payroll | G37: =IFERROR(VLOOKUP($F37,ItemList_Full,2,0),"") | I37: =IFERROR(VLOOKUP($F37,ItemList_Full,3,0),"") | J37: =IFERROR(VLOOKUP($F37,ItemList_Full,4,0),"") | K37: 1450 | N37: Zeeshan (Sept import) | P37: =IF($E37="","",IF(OR($E37="Director Draw",$E37="Payroll/Employee Charge"),0,-$K37)) -> -1450 | Q37: =IF($E37="Inventory Purchase",$H37,0) -> 0 | U37: FD-033 | V37: AL BARKA WATER BAR | W37: BOT | X37: 16000 | Y37: Food & Beverage
A38: 46267 | B38: =IF($A38="","",ROW()-4) -> 34 | C38: BOH | D38: ARSLAN ALI K/A | E38: Payroll | G38: =IFERROR(VLOOKUP($F38,ItemList_Full,2,0),"") | I38: =IFERROR(VLOOKUP($F38,ItemList_Full,3,0),"") | J38: =IFERROR(VLOOKUP($F38,ItemList_Full,4,0),"") | K38: 2000 | N38: Zeeshan (Sept import) | P38: =IF($E38="","",IF(OR($E38="Director Draw",$E38="Payroll/Employee Charge"),0,-$K38)) -> -2000 | Q38: =IF($E38="Inventory Purchase",$H38,0) -> 0 | U38: FD-034 | V38: MIRINDA FEGILE | W38: CYL | X38: 8211 | Y38: Food & Beverage
A39: 46267 | B39: =IF($A39="","",ROW()-4) -> 35 | C39: DELIVERY | D39: TAYYAB RIDER | E39: Payroll | G39: =IFERROR(VLOOKUP($F39,ItemList_Full,2,0),"") | I39: =IFERROR(VLOOKUP($F39,ItemList_Full,3,0),"") | J39: =IFERROR(VLOOKUP($F39,ItemList_Full,4,0),"") | K39: 550 | N39: Zeeshan (Sept import) | P39: =IF($E39="","",IF(OR($E39="Director Draw",$E39="Payroll/Employee Charge"),0,-$K39)) -> -550 | Q39: =IF($E39="Inventory Purchase",$H39,0) -> 0 | U39: FD-035 | V39: PEPSI 1500 ML | W39: PET | X39: 891 | Y39: Food & Beverage
... A42: 46267 | B42: =IF($A42="","",ROW()-4) -> 38 | C42: SIM | D42: NEW SIM PURCHASE FOR JAZZ CASH | E42: Utilities (Electricity/Water) | G42: =IFERROR(VLOOKUP($F42,ItemList_Full,2,0),"") | I42: =IFERROR(VLOOKUP($F42,ItemList_Full,3,0),"") | J42: =IFERROR(VLOOKUP($F42,ItemList_Full,4,0),"") | K42: 2100 | N42: Zeeshan (Sept import) | P42: =IF($E42="","",IF(OR($E42="Director Draw",$E42="Payroll/Employee Charge"),0,-$K42)) -> -2100 | Q42: =IF($E42="Inventory Purchase",$H42,0) -> 0 | U42: FD-038 | V42: GOURMENT 345 ML | W42: PET | X42: 610 | Y42: Food & Beverage
A43: 46268 | B43: =IF($A43="","",ROW()-4) -> 39 | C43: - | D43: QR JAZZ CASH PAYMENT | E43: Director Draw | G43: =IFERROR(VLOOKUP($F43,ItemList_Full,2,0),"") | I43: =IFERROR(VLOOKUP($F43,ItemList_Full,3,0),"") | J43: =IFERROR(VLOOKUP($F43,ItemList_Full,4,0),"") | K43: 13560 | M43: Yasir Sb | N43: Zeeshan (Sept import) | P43: =IF($E43="","",IF(OR($E43="Director Draw",$E43="Payroll/Employee Charge"),0,-$K43)) -> 0 | Q43: =IF($E43="Inventory Purchase",$H43,0) -> 0 | U43: FD-039 | V43: NUGGETS | W43: PKT | X43: 975 | Y43: Food & Beverage
A44: 46268 | B44: =IF($A44="","",ROW()-4) -> 40 | C44: - | D44: CASH GIVEN TO YASIR SB | E44: Director Draw | G44: =IFERROR(VLOOKUP($F44,ItemList_Full,2,0),"") | I44: =IFERROR(VLOOKUP($F44,ItemList_Full,3,0),"") | J44: =IFERROR(VLOOKUP($F44,ItemList_Full,4,0),"") | K44: 10000 | M44: Yasir Sb | N44: Zeeshan (Sept import) | P44: =IF($E44="","",IF(OR($E44="Director Draw",$E44="Payroll/Employee Charge"),0,-$K44)) -> 0 | Q44: =IF($E44="Inventory Purchase",$H44,0) -> 0 | U44: FD-040 | V44: FRIED FLOUR | W44: KG | X44: 166.5 | Y44: Food & Beverage
A45: 46268 | B45: =IF($A45="","",ROW()-4) -> 41 | C45: - | D45: PARCAL PAYMENT FOR YASIR SB | E45: Director Draw | G45: =IFERROR(VLOOKUP($F45,ItemList_Full,2,0),"") | I45: =IFERROR(VLOOKUP($F45,ItemList_Full,3,0),"") | J45: =IFERROR(VLOOKUP($F45,ItemList_Full,4,0),"") | K45: 4630 | M45: Yasir Sb | N45: Zeeshan (Sept import) | P45: =IF($E45="","",IF(OR($E45="Director Draw",$E45="Payroll/Employee Charge"),0,-$K45)) -> 0 | Q45: =IF($E45="Inventory Purchase",$H45,0) -> 0 | U45: FD-041 | V45: MARINATED FRIED FLOUR | W45: BAG | X45: 2250 | Y45: Food & Beverage
A46: 46268 | B46: =IF($A46="","",ROW()-4) -> 42 | C46: - | D46: DELIVERY INV# 39 MEAL FOR HASSAN NASIR SB | E46: Director Draw | G46: =IFERROR(VLOOKUP($F46,ItemList_Full,2,0),"") | I46: =IFERROR(VLOOKUP($F46,ItemList_Full,3,0),"") | J46: =IFERROR(VLOOKUP($F46,ItemList_Full,4,0),"") | K46: 3015 | M46: Hassan Nasir | N46: Zeeshan (Sept import) | P46: =IF($E46="","",IF(OR($E46="Director Draw",$E46="Payroll/Employee Charge"),0,-$K46)) -> 0 | Q46: =IF($E46="Inventory Purchase",$H46,0) -> 0 | U46: FD-042 | V46: OIL 16 LITTER'S | W46: TIN | X46: 8000 | Y46: Food & Beverage
A47: 46268 | B47: =IF($A47="","",ROW()-4) -> 43 | C47: - | D47: T.A INV# 04 MEAL FOR IMRAN TAHIR SB | E47: Director Draw | G47: =IFERROR(VLOOKUP($F47,ItemList_Full,2,0),"") | I47: =IFERROR(VLOOKUP($F47,ItemList_Full,3,0),"") | J47: =IFERROR(VLOOKUP($F47,ItemList_Full,4,0),"") | K47: 620 | M47: Imran Tahir | N47: Zeeshan (Sept import) | P47: =IF($E47="","",IF(OR($E47="Director Draw",$E47="Payroll/Employee Charge"),0,-$K47)) -> 0 | Q47: =IF($E47="Inventory Purchase",$H47,0) -> 0 | U47: FD-043 | V47: GOLDEN BROWN FRIES | W47: PKT | X47: 937.5 | Y47: Food & Beverage
...

Sheet Purchase Orders
A1: PURCHASE ORDERS — demand -> authorize -> receive
A2: Hammad raises demand, Imran/Owner authorizes, Store person marks Received when goods arrive. Pick the standard Item Code. A row with Status=Received automatically creates a Payable and adds stock to the Inventory tab.
A4: PO# | B4: Date Ordered | C4: Vendor | D4: Item Code | E4: Item Name (auto) | F4: Qty | G4: Unit | H4: Rate | I4: Amount (PKR) | J4: Requested By | K4: Authorized By | L4: Status | M4: Date Received
A5: =IF($C5="","","PO-"&TEXT(ROW()-4,"000")) | E5: =IFERROR(VLOOKUP($D5,ItemList_Full,2,0),"") | G5: =IFERROR(VLOOKUP($D5,ItemList_Full,3,0),"") | H5: =IFERROR(VLOOKUP($D5,ItemList_Full,4,0),"") | I5: =IF(OR($F5="",$H5=""),"",$F5*$H5)
A6: =IF($C6="","","PO-"&TEXT(ROW()-4,"000")) | E6: =IFERROR(VLOOKUP($D6,ItemList_Full,2,0),"") | G6: =IFERROR(VLOOKUP($D6,ItemList_Full,3,0),"") | H6: =IFERROR(VLOOKUP($D6,ItemList_Full,4,0),"") | I6: =IF(OR($F6="",$H6=""),"",$F6*$H6)
A7: =IF($C7="","","PO-"&TEXT(ROW()-4,"000")) | E7: =IFERROR(VLOOKUP($D7,ItemList_Full,2,0),"") | G7: =IFERROR(VLOOKUP($D7,ItemList_Full,3,0),"") | H7: =IFERROR(VLOOKUP($D7,ItemList_Full,4,0),"") | I7: =IF(OR($F7="",$H7=""),"",$F7*$H7)
A8: =IF($C8="","","PO-"&TEXT(ROW()-4,"000")) | E8: =IFERROR(VLOOKUP($D8,ItemList_Full,2,0),"") | G8: =IFERROR(VLOOKUP($D8,ItemList_Full,3,0),"") | H8: =IFERROR(VLOOKUP($D8,ItemList_Full,4,0),"") | I8: =IF(OR($F8="",$H8=""),"",$F8*$H8)
A9: =IF($C9="","","PO-"&TEXT(ROW()-4,"000")) | E9: =IFERROR(VLOOKUP($D9,ItemList_Full,2,0),"") | G9: =IFERROR(VLOOKUP($D9,ItemList_Full,3,0),"") | H9: =IFERROR(VLOOKUP($D9,ItemList_Full,4,0),"") | I9: =IF(OR($F9="",$H9=""),"",$F9*$H9)
A10: =IF($C10="","","PO-"&TEXT(ROW()-4,"000")) | E10: =IFERROR(VLOOKUP($D10,ItemList_Full,2,0),"") | G10: =IFERROR(VLOOKUP($D10,ItemList_Full,3,0),"") | H10: =IFERROR(VLOOKUP($D10,ItemList_Full,4,0),"") | I10: =IF(OR($F10="",$H10=""),"",$F10*$H10)
A11: =IF($C11="","","PO-"&TEXT(ROW()-4,"000")) | E11: =IFERROR(VLOOKUP($D11,ItemList_Full,2,0),"") | G11: =IFERROR(VLOOKUP($D11,ItemList_Full,3,0),"") | H11: =IFERROR(VLOOKUP($D11,ItemList_Full,4,0),"") | I11: =IF(OR($F11="",$H11=""),"",$F11*$H11)
A12: =IF($C12="","","PO-"&TEXT(ROW()-4,"000")) | E12: =IFERROR(VLOOKUP($D12,ItemList_Full,2,0),"") | G12: =IFERROR(VLOOKUP($D12,ItemList_Full,3,0),"") | H12: =IFERROR(VLOOKUP($D12,ItemList_Full,4,0),"") | I12: =IF(OR($F12="",$H12=""),"",$F12*$H12)
A13: =IF($C13="","","PO-"&TEXT(ROW()-4,"000")) | E13: =IFERROR(VLOOKUP($D13,ItemList_Full,2,0),"") | G13: =IFERROR(VLOOKUP($D13,ItemList_Full,3,0),"") | H13: =IFERROR(VLOOKUP($D13,ItemList_Full,4,0),"") | I13: =IF(OR($F13="",$H13=""),"",$F13*$H13)
A14: =IF($C14="","","PO-"&TEXT(ROW()-4,"000")) | E14: =IFERROR(VLOOKUP($D14,ItemList_Full,2,0),"") | G14: =IFERROR(VLOOKUP($D14,ItemList_Full,3,0),"") | H14: =IFERROR(VLOOKUP($D14,ItemList_Full,4,0),"") | I14: =IF(OR($F14="",$H14=""),"",$F14*$H14)
A15: =IF($C15="","","PO-"&TEXT(ROW()-4,"000")) | E15: =IFERROR(VLOOKUP($D15,ItemList_Full,2,0),"") | G15: =IFERROR(VLOOKUP($D15,ItemList_Full,3,0),"") | H15: =IFERROR(VLOOKUP($D15,ItemList_Full,4,0),"") | I15: =IF(OR($F15="",$H15=""),"",$F15*$H15)
A16: =IF($C16="","","PO-"&TEXT(ROW()-4,"000")) | E16: =IFERROR(VLOOKUP($D16,ItemList_Full,2,0),"") | G16: =IFERROR(VLOOKUP($D16,ItemList_Full,3,0),"") | H16: =IFERROR(VLOOKUP($D16,ItemList_Full,4,0),"") | I16: =IF(OR($F16="",$H16=""),"",$F16*$H16)
... A304: =IF($C304="","","PO-"&TEXT(ROW()-4,"000")) | E304: =IFERROR(VLOOKUP($D304,ItemList_Full,2,0),"") | G304: =IFERROR(VLOOKUP($D304,ItemList_Full,3,0),"") | H304: =IFERROR(VLOOKUP($D304,ItemList_Full,4,0),"") | I304: =IF(OR($F304="",$H304=""),"",$F304*$H304)

Sheet Payables
A1: PAYABLES — auto-generated from Received Purchase Orders
A2: One row per Purchase Order marked Received. 'Paid to Date' pulls Payable Payment entries from Expense Entry linked by PO#.
A4: PO# | B4: Vendor | C4: Item Code | D4: Item Name | E4: Amount Owed | F4: Paid to Date | G4: Balance | H4: Status
A5: =IF('Purchase Orders'!$L5="Received",'Purchase Orders'!$A5,"") | B5: =IF($A5="","",'Purchase Orders'!$C5) | C5: =IF($A5="","",'Purchase Orders'!$D5) | D5: =IF($A5="","",'Purchase Orders'!$E5) | E5: =IF($A5="","",'Purchase Orders'!$I5) | F5: =IF($A5="","",SUMIFS('Expense Entry'!$K$5:$K$6000,'Expense Entry'!$E$5:$E$6000,"Payable Payment",'Expense Entry'!$L$5:$L$6000,$A5)) | G5: =IF($A5="","",$E5-$F5) | H5: =IF($A5="","",IF($G5<=0,"Paid",IF($F5>0,"Partial","Unpaid")))
A6: =IF('Purchase Orders'!$L6="Received",'Purchase Orders'!$A6,"") | B6: =IF($A6="","",'Purchase Orders'!$C6) | C6: =IF($A6="","",'Purchase Orders'!$D6) | D6: =IF($A6="","",'Purchase Orders'!$E6) | E6: =IF($A6="","",'Purchase Orders'!$I6) | F6: =IF($A6="","",SUMIFS('Expense Entry'!$K$5:$K$6000,'Expense Entry'!$E$5:$E$6000,"Payable Payment",'Expense Entry'!$L$5:$L$6000,$A6)) | G6: =IF($A6="","",$E6-$F6) | H6: =IF($A6="","",IF($G6<=0,"Paid",IF($F6>0,"Partial","Unpaid")))
A7: =IF('Purchase Orders'!$L7="Received",'Purchase Orders'!$A7,"") | B7: =IF($A7="","",'Purchase Orders'!$C7) | C7: =IF($A7="","",'Purchase Orders'!$D7) | D7: =IF($A7="","",'Purchase Orders'!$E7) | E7: =IF($A7="","",'Purchase Orders'!$I7) | F7: =IF($A7="","",SUMIFS('Expense Entry'!$K$5:$K$6000,'Expense Entry'!$E$5:$E$6000,"Payable Payment",'Expense Entry'!$L$5:$L$6000,$A7)) | G7: =IF($A7="","",$E7-$F7) | H7: =IF($A7="","",IF($G7<=0,"Paid",IF($F7>0,"Partial","Unpaid")))
A8: =IF('Purchase Orders'!$L8="Received",'Purchase Orders'!$A8,"") | B8: =IF($A8="","",'Purchase Orders'!$C8) | C8: =IF($A8="","",'Purchase Orders'!$D8) | D8: =IF($A8="","",'Purchase Orders'!$E8) | E8: =IF($A8="","",'Purchase Orders'!$I8) | F8: =IF($A8="","",SUMIFS('Expense Entry'!$K$5:$K$6000,'Expense Entry'!$E$5:$E$6000,"Payable Payment",'Expense Entry'!$L$5:$L$6000,$A8)) | G8: =IF($A8="","",$E8-$F8) | H8: =IF($A8="","",IF($G8<=0,"Paid",IF($F8>0,"Partial","Unpaid")))
A9: =IF('Purchase Orders'!$L9="Received",'Purchase Orders'!$A9,"") | B9: =IF($A9="","",'Purchase Orders'!$C9) | C9: =IF($A9="","",'Purchase Orders'!$D9) | D9: =IF($A9="","",'Purchase Orders'!$E9) | E9: =IF($A9="","",'Purchase Orders'!$I9) | F9: =IF($A9="","",SUMIFS('Expense Entry'!$K$5:$K$6000,'Expense Entry'!$E$5:$E$6000,"Payable Payment",'Expense Entry'!$L$5:$L$6000,$A9)) | G9: =IF($A9="","",$E9-$F9) | H9: =IF($A9="","",IF($G9<=0,"Paid",IF($F9>0,"Partial","Unpaid")))
A10: =IF('Purchase Orders'!$L10="Received",'Purchase Orders'!$A10,"") | B10: =IF($A10="","",'Purchase Orders'!$C10) | C10: =IF($A10="","",'Purchase Orders'!$D10) | D10: =IF($A10="","",'Purchase Orders'!$E10) | E10: =IF($A10="","",'Purchase Orders'!$I10) | F10: =IF($A10="","",SUMIFS('Expense Entry'!$K$5:$K$6000,'Expense Entry'!$E$5:$E$6000,"Payable Payment",'Expense Entry'!$L$5:$L$6000,$A10)) | G10: =IF($A10="","",$E10-$F10) | H10: =IF($A10="","",IF($G10<=0,"Paid",IF($F10>0,"Partial","Unpaid")))
A11: =IF('Purchase Orders'!$L11="Received",'Purchase Orders'!$A11,"") | B11: =IF($A11="","",'Purchase Orders'!$C11) | C11: =IF($A11="","",'Purchase Orders'!$D11) | D11: =IF($A11="","",'Purchase Orders'!$E11) | E11: =IF($A11="","",'Purchase Orders'!$I11) | F11: =IF($A11="","",SUMIFS('Expense Entry'!$K$5:$K$6000,'Expense Entry'!$E$5:$E$6000,"Payable Payment",'Expense Entry'!$L$5:$L$6000,$A11)) | G11: =IF($A11="","",$E11-$F11) | H11: =IF($A11="","",IF($G11<=0,"Paid",IF($F11>0,"Partial","Unpaid")))
A12: =IF('Purchase Orders'!$L12="Received",'Purchase Orders'!$A12,"") | B12: =IF($A12="","",'Purchase Orders'!$C12) | C12: =IF($A12="","",'Purchase Orders'!$D12) | D12: =IF($A12="","",'Purchase Orders'!$E12) | E12: =IF($A12="","",'Purchase Orders'!$I12) | F12: =IF($A12="","",SUMIFS('Expense Entry'!$K$5:$K$6000,'Expense Entry'!$E$5:$E$6000,"Payable Payment",'Expense Entry'!$L$5:$L$6000,$A12)) | G12: =IF($A12="","",$E12-$F12) | H12: =IF($A12="","",IF($G12<=0,"Paid",IF($F12>0,"Partial","Unpaid")))
A13: =IF('Purchase Orders'!$L13="Received",'Purchase Orders'!$A13,"") | B13: =IF($A13="","",'Purchase Orders'!$C13) | C13: =IF($A13="","",'Purchase Orders'!$D13) | D13: =IF($A13="","",'Purchase Orders'!$E13) | E13: =IF($A13="","",'Purchase Orders'!$I13) | F13: =IF($A13="","",SUMIFS('Expense Entry'!$K$5:$K$6000,'Expense Entry'!$E$5:$E$6000,"Payable Payment",'Expense Entry'!$L$5:$L$6000,$A13)) | G13: =IF($A13="","",$E13-$F13) | H13: =IF($A13="","",IF($G13<=0,"Paid",IF($F13>0,"Partial","Unpaid")))
A14: =IF('Purchase Orders'!$L14="Received",'Purchase Orders'!$A14,"") | B14: =IF($A14="","",'Purchase Orders'!$C14) | C14: =IF($A14="","",'Purchase Orders'!$D14) | D14: =IF($A14="","",'Purchase Orders'!$E14) | E14: =IF($A14="","",'Purchase Orders'!$I14) | F14: =IF($A14="","",SUMIFS('Expense Entry'!$K$5:$K$6000,'Expense Entry'!$E$5:$E$6000,"Payable Payment",'Expense Entry'!$L$5:$L$6000,$A14)) | G14: =IF($A14="","",$E14-$F14) | H14: =IF($A14="","",IF($G14<=0,"Paid",IF($F14>0,"Partial","Unpaid")))
A15: =IF('Purchase Orders'!$L15="Received",'Purchase Orders'!$A15,"") | B15: =IF($A15="","",'Purchase Orders'!$C15) | C15: =IF($A15="","",'Purchase Orders'!$D15) | D15: =IF($A15="","",'Purchase Orders'!$E15) | E15: =IF($A15="","",'Purchase Orders'!$I15) | F15: =IF($A15="","",SUMIFS('Expense Entry'!$K$5:$K$6000,'Expense Entry'!$E$5:$E$6000,"Payable Payment",'Expense Entry'!$L$5:$L$6000,$A15)) | G15: =IF($A15="","",$E15-$F15) | H15: =IF($A15="","",IF($G15<=0,"Paid",IF($F15>0,"Partial","Unpaid")))
A16: =IF('Purchase Orders'!$L16="Received",'Purchase Orders'!$A16,"") | B16: =IF($A16="","",'Purchase Orders'!$C16) | C16: =IF($A16="","",'Purchase Orders'!$D16) | D16: =IF($A16="","",'Purchase Orders'!$E16) | E16: =IF($A16="","",'Purchase Orders'!$I16) | F16: =IF($A16="","",SUMIFS('Expense Entry'!$K$5:$K$6000,'Expense Entry'!$E$5:$E$6000,"Payable Payment",'Expense Entry'!$L$5:$L$6000,$A16)) | G16: =IF($A16="","",$E16-$F16) | H16: =IF($A16="","",IF($G16<=0,"Paid",IF($F16>0,"Partial","Unpaid")))
... A304: =IF('Purchase Orders'!$L304="Received",'Purchase Orders'!$A304,"") | B304: =IF($A304="","",'Purchase Orders'!$C304) | C304: =IF($A304="","",'Purchase Orders'!$D304) | D304: =IF($A304="","",'Purchase Orders'!$E304) | E304: =IF($A304="","",'Purchase Orders'!$I304) | F304: =IF($A304="","",SUMIFS('Expense Entry'!$K$5:$K$6000,'Expense Entry'!$E$5:$E$6000,"Payable Payment",'Expense Entry'!$L$5:$L$6000,$A304)) | G304: =IF($A304="","",$E304-$F304) | H304: =IF($A304="","",IF($G304<=0,"Paid",IF($F304>0,"Partial","Unpaid")))

Sheet Issue Log
A1: ISSUE LOG — stock issued from store to kitchen (becomes cost of goods used)
A2: Store person logs what leaves the store room each day, by Item Code. This is what actually drives Food/Packaging/Cleaning/etc. cost in the P&L — not the purchase date.
A4: Date | B4: Item Code | C4: Item Name (auto) | D4: Unit | E4: Qty Issued | F4: Rate | G4: Value (PKR) | H4: Issued By | I4: Notes | J4: Category (lookup, hidden)
C5: =IFERROR(VLOOKUP($B5,ItemList_Full,2,0),"") | D5: =IFERROR(VLOOKUP($B5,ItemList_Full,3,0),"") | F5: =IFERROR(VLOOKUP($B5,ItemList_Full,4,0),"") | G5: =IF(OR($E5="",$F5=""),"",$E5*$F5) | J5: =IFERROR(VLOOKUP($B5,ItemList_Full,5,0),"")
C6: =IFERROR(VLOOKUP($B6,ItemList_Full,2,0),"") | D6: =IFERROR(VLOOKUP($B6,ItemList_Full,3,0),"") | F6: =IFERROR(VLOOKUP($B6,ItemList_Full,4,0),"") | G6: =IF(OR($E6="",$F6=""),"",$E6*$F6) | J6: =IFERROR(VLOOKUP($B6,ItemList_Full,5,0),"")
C7: =IFERROR(VLOOKUP($B7,ItemList_Full,2,0),"") | D7: =IFERROR(VLOOKUP($B7,ItemList_Full,3,0),"") | F7: =IFERROR(VLOOKUP($B7,ItemList_Full,4,0),"") | G7: =IF(OR($E7="",$F7=""),"",$E7*$F7) | J7: =IFERROR(VLOOKUP($B7,ItemList_Full,5,0),"")
C8: =IFERROR(VLOOKUP($B8,ItemList_Full,2,0),"") | D8: =IFERROR(VLOOKUP($B8,ItemList_Full,3,0),"") | F8: =IFERROR(VLOOKUP($B8,ItemList_Full,4,0),"") | G8: =IF(OR($E8="",$F8=""),"",$E8*$F8) | J8: =IFERROR(VLOOKUP($B8,ItemList_Full,5,0),"")
C9: =IFERROR(VLOOKUP($B9,ItemList_Full,2,0),"") | D9: =IFERROR(VLOOKUP($B9,ItemList_Full,3,0),"") | F9: =IFERROR(VLOOKUP($B9,ItemList_Full,4,0),"") | G9: =IF(OR($E9="",$F9=""),"",$E9*$F9) | J9: =IFERROR(VLOOKUP($B9,ItemList_Full,5,0),"")
C10: =IFERROR(VLOOKUP($B10,ItemList_Full,2,0),"") | D10: =IFERROR(VLOOKUP($B10,ItemList_Full,3,0),"") | F10: =IFERROR(VLOOKUP($B10,ItemList_Full,4,0),"") | G10: =IF(OR($E10="",$F10=""),"",$E10*$F10) | J10: =IFERROR(VLOOKUP($B10,ItemList_Full,5,0),"")
C11: =IFERROR(VLOOKUP($B11,ItemList_Full,2,0),"") | D11: =IFERROR(VLOOKUP($B11,ItemList_Full,3,0),"") | F11: =IFERROR(VLOOKUP($B11,ItemList_Full,4,0),"") | G11: =IF(OR($E11="",$F11=""),"",$E11*$F11) | J11: =IFERROR(VLOOKUP($B11,ItemList_Full,5,0),"")
C12: =IFERROR(VLOOKUP($B12,ItemList_Full,2,0),"") | D12: =IFERROR(VLOOKUP($B12,ItemList_Full,3,0),"") | F12: =IFERROR(VLOOKUP($B12,ItemList_Full,4,0),"") | G12: =IF(OR($E12="",$F12=""),"",$E12*$F12) | J12: =IFERROR(VLOOKUP($B12,ItemList_Full,5,0),"")
C13: =IFERROR(VLOOKUP($B13,ItemList_Full,2,0),"") | D13: =IFERROR(VLOOKUP($B13,ItemList_Full,3,0),"") | F13: =IFERROR(VLOOKUP($B13,ItemList_Full,4,0),"") | G13: =IF(OR($E13="",$F13=""),"",$E13*$F13) | J13: =IFERROR(VLOOKUP($B13,ItemList_Full,5,0),"")
C14: =IFERROR(VLOOKUP($B14,ItemList_Full,2,0),"") | D14: =IFERROR(VLOOKUP($B14,ItemList_Full,3,0),"") | F14: =IFERROR(VLOOKUP($B14,ItemList_Full,4,0),"") | G14: =IF(OR($E14="",$F14=""),"",$E14*$F14) | J14: =IFERROR(VLOOKUP($B14,ItemList_Full,5,0),"")
C15: =IFERROR(VLOOKUP($B15,ItemList_Full,2,0),"") | D15: =IFERROR(VLOOKUP($B15,ItemList_Full,3,0),"") | F15: =IFERROR(VLOOKUP($B15,ItemList_Full,4,0),"") | G15: =IF(OR($E15="",$F15=""),"",$E15*$F15) | J15: =IFERROR(VLOOKUP($B15,ItemList_Full,5,0),"")
C16: =IFERROR(VLOOKUP($B16,ItemList_Full,2,0),"") | D16: =IFERROR(VLOOKUP($B16,ItemList_Full,3,0),"") | F16: =IFERROR(VLOOKUP($B16,ItemList_Full,4,0),"") | G16: =IF(OR($E16="",$F16=""),"",$E16*$F16) | J16: =IFERROR(VLOOKUP($B16,ItemList_Full,5,0),"")
... C604: =IFERROR(VLOOKUP($B604,ItemList_Full,2,0),"") | D604: =IFERROR(VLOOKUP($B604,ItemList_Full,3,0),"") | F604: =IFERROR(VLOOKUP($B604,ItemList_Full,4,0),"") | G604: =IF(OR($E604="",$F604=""),"",$E604*$F604) | J604: =IFERROR(VLOOKUP($B604,ItemList_Full,5,0),"")

Sheet Inventory
A1: INVENTORY — live stock ledger, one row per item code
A2: Opening Stock: enter once at month start. Received columns and Issued pull automatically from Expense Entry / Purchase Orders / Issue Log, matched by Item Code.
A4: Item Code | B4: Item Name | C4: Category | D4: Unit | E4: Std Rate | F4: Opening Stock | G4: Received (Cash Purchase) | H4: Received (via PO) | I4: Total Received | J4: Issued | K4: Closing Stock | L4: Closing Value (PKR)
A5: FD-001 | B5: CHEESE YELLOW | C5: Food & Beverage | D5: CTN | E5: 16900 | F5: 23 | G5: =SUMIFS('Expense Entry'!$H$5:$H$6000,'Expense Entry'!$E$5:$E$6000,"Inventory Purchase",'Expense Entry'!$F$5:$F$6000,$A5) -> 0 | H5: =SUMIFS('Purchase Orders'!$F$5:$F$3000,'Purchase Orders'!$L$5:$L$3000,"Received",'Purchase Orders'!$D$5:$D$3000,$A5) -> 0 | I5: =$G5+$H5 -> 0 | J5: =SUMIFS('Issue Log'!$E$5:$E$6000,'Issue Log'!$B$5:$B$6000,$A5) -> 0 | K5: =$F5+$I5-$J5 -> 23 | L5: =$K5*$E5 -> 388700
A6: FD-002 | B6: CHEESE GREEN | C6: Food & Beverage | D6: CTN | E6: 16900 | F6: 26 | G6: =SUMIFS('Expense Entry'!$H$5:$H$6000,'Expense Entry'!$E$5:$E$6000,"Inventory Purchase",'Expense Entry'!$F$5:$F$6000,$A6) -> 0 | H6: =SUMIFS('Purchase Orders'!$F$5:$F$3000,'Purchase Orders'!$L$5:$L$3000,"Received",'Purchase Orders'!$D$5:$D$3000,$A6) -> 0 | I6: =$G6+$H6 -> 0 | J6: =SUMIFS('Issue Log'!$E$5:$E$6000,'Issue Log'!$B$5:$B$6000,$A6) -> 0 | K6: =$F6+$I6-$J6 -> 26 | L6: =$K6*$E6 -> 439400
A7: FD-003 | B7: MALAI BOTI | C7: Food & Beverage | D7: KG | E7: 1400 | F7: 25 | G7: =SUMIFS('Expense Entry'!$H$5:$H$6000,'Expense Entry'!$E$5:$E$6000,"Inventory Purchase",'Expense Entry'!$F$5:$F$6000,$A7) -> 0 | H7: =SUMIFS('Purchase Orders'!$F$5:$F$3000,'Purchase Orders'!$L$5:$L$3000,"Received",'Purchase Orders'!$D$5:$D$3000,$A7) -> 0 | I7: =$G7+$H7 -> 0 | J7: =SUMIFS('Issue Log'!$E$5:$E$6000,'Issue Log'!$B$5:$B$6000,$A7) -> 0 | K7: =$F7+$I7-$J7 -> 25 | L7: =$K7*$E7 -> 35000
A8: FD-004 | B8: STEAK FILLET | C8: Food & Beverage | D8: PCS | E8: 200 | F8: 45 | G8: =SUMIFS('Expense Entry'!$H$5:$H$6000,'Expense Entry'!$E$5:$E$6000,"Inventory Purchase",'Expense Entry'!$F$5:$F$6000,$A8) -> 0 | H8: =SUMIFS('Purchase Orders'!$F$5:$F$3000,'Purchase Orders'!$L$5:$L$3000,"Received",'Purchase Orders'!$D$5:$D$3000,$A8) -> 0 | I8: =$G8+$H8 -> 0 | J8: =SUMIFS('Issue Log'!$E$5:$E$6000,'Issue Log'!$B$5:$B$6000,$A8) -> 0 | K8: =$F8+$I8-$J8 -> 45 | L8: =$K8*$E8 -> 9000
A9: FD-005 | B9: BEHARI CHICKEN | C9: Food & Beverage | D9: KG | E9: 1150 | F9: 0 | G9: =SUMIFS('Expense Entry'!$H$5:$H$6000,'Expense Entry'!$E$5:$E$6000,"Inventory Purchase",'Expense Entry'!$F$5:$F$6000,$A9) -> 0 | H9: =SUMIFS('Purchase Orders'!$F$5:$F$3000,'Purchase Orders'!$L$5:$L$3000,"Received",'Purchase Orders'!$D$5:$D$3000,$A9) -> 0 | I9: =$G9+$H9 -> 0 | J9: =SUMIFS('Issue Log'!$E$5:$E$6000,'Issue Log'!$B$5:$B$6000,$A9) -> 0 | K9: =$F9+$I9-$J9 -> 0 | L9: =$K9*$E9 -> 0
A10: FD-006 | B10: TIKKA TOPPING FISH AND CHICK | C10: Food & Beverage | D10: KG | E10: 1150 | F10: 0 | G10: =SUMIFS('Expense Entry'!$H$5:$H$6000,'Expense Entry'!$E$5:$E$6000,"Inventory Purchase",'Expense Entry'!$F$5:$F$6000,$A10) -> 0 | H10: =SUMIFS('Purchase Orders'!$F$5:$F$3000,'Purchase Orders'!$L$5:$L$3000,"Received",'Purchase Orders'!$D$5:$D$3000,$A10) -> 0 | I10: =$G10+$H10 -> 0 | J10: =SUMIFS('Issue Log'!$E$5:$E$6000,'Issue Log'!$B$5:$B$6000,$A10) -> 0 | K10: =$F10+$I10-$J10 -> 0 | L10: =$K10*$E10 -> 0
A11: FD-007 | B11: FAJITA TOPPING FISH AND CHICK | C11: Food & Beverage | D11: KG | E11: 1150 | F11: 0 | G11: =SUMIFS('Expense Entry'!$H$5:$H$6000,'Expense Entry'!$E$5:$E$6000,"Inventory Purchase",'Expense Entry'!$F$5:$F$6000,$A11) -> 0 | H11: =SUMIFS('Purchase Orders'!$F$5:$F$3000,'Purchase Orders'!$L$5:$L$3000,"Received",'Purchase Orders'!$D$5:$D$3000,$A11) -> 0 | I11: =$G11+$H11 -> 0 | J11: =SUMIFS('Issue Log'!$E$5:$E$6000,'Issue Log'!$B$5:$B$6000,$A11) -> 0 | K11: =$F11+$I11-$J11 -> 0 | L11: =$K11*$E11 -> 0
A12: FD-008 | B12: AL-TAYYAB DRUMMET | C12: Food & Beverage | D12: KG | E12: 800 | F12: 0 | G12: =SUMIFS('Expense Entry'!$H$5:$H$6000,'Expense Entry'!$E$5:$E$6000,"Inventory Purchase",'Expense Entry'!$F$5:$F$6000,$A12) -> 0 | H12: =SUMIFS('Purchase Orders'!$F$5:$F$3000,'Purchase Orders'!$L$5:$L$3000,"Received",'Purchase Orders'!$D$5:$D$3000,$A12) -> 0 | I12: =$G12+$H12 -> 0 | J12: =SUMIFS('Issue Log'!$E$5:$E$6000,'Issue Log'!$B$5:$B$6000,$A12) -> 0 | K12: =$F12+$I12-$J12 -> 0 | L12: =$K12*$E12 -> 0
A13: FD-009 | B13: WINGS | C13: Food & Beverage | D13: PKT | E13: 1260 | F13: 4 | G13: =SUMIFS('Expense Entry'!$H$5:$H$6000,'Expense Entry'!$E$5:$E$6000,"Inventory Purchase",'Expense Entry'!$F$5:$F$6000,$A13) -> 0 | H13: =SUMIFS('Purchase Orders'!$F$5:$F$3000,'Purchase Orders'!$L$5:$L$3000,"Received",'Purchase Orders'!$D$5:$D$3000,$A13) -> 0 | I13: =$G13+$H13 -> 0 | J13: =SUMIFS('Issue Log'!$E$5:$E$6000,'Issue Log'!$B$5:$B$6000,$A13) -> 0 | K13: =$F13+$I13-$J13 -> 4 | L13: =$K13*$E13 -> 5040
A14: FD-010 | B14: DRUMMETTE | C14: Food & Beverage | D14: PKT | E14: 1301 | F14: 16 | G14: =SUMIFS('Expense Entry'!$H$5:$H$6000,'Expense Entry'!$E$5:$E$6000,"Inventory Purchase",'Expense Entry'!$F$5:$F$6000,$A14) -> 0 | H14: =SUMIFS('Purchase Orders'!$F$5:$F$3000,'Purchase Orders'!$L$5:$L$3000,"Received",'Purchase Orders'!$D$5:$D$3000,$A14) -> 0 | I14: =$G14+$H14 -> 0 | J14: =SUMIFS('Issue Log'!$E$5:$E$6000,'Issue Log'!$B$5:$B$6000,$A14) -> 0 | K14: =$F14+$I14-$J14 -> 16 | L14: =$K14*$E14 -> 20816
